Workbook
Name Z_56799CC1_F484_4137_8B81_ABA0C19A048B_.wvu.PrintArea: 'Course Ass report'!$A$1:$O$35

Sheet Target
A1: KONGU ENGINEERING COLLEGE, ERODE - 638 060
A2: DEPARTMENT OF ________________________________________
A3: THEORY CUM LABORATORY COURSE OUTCOME ANALYSIS - TARGET FIXING
A4: S.NO | B4: (X-2) SEM | H4: (X-1) SEM
B5: A Sec | C5: B sec | D5: C Sec | E5: D Sec | F5: E Sec | G5: F Sec | H5: A Sec | I5: B sec | J5: C Sec | K5: D Sec | L5: E Sec | M5: F Sec
A6: 1
A7: 2
A8: 3
A9: 4
A10: 5
A11: 6
A12: 7
A13: 8
A14: 9
A15: 10
A16: 11
A17: 12
... A75: 70
A77: Mean of individual class GPA(a.) | B77: =IFERROR(AVERAGE(B6:B76),0) -> 0 | C77: =IFERROR(AVERAGE(C6:C76),0) -> 0 | D77: =IFERROR(AVERAGE(D6:D76),0) -> 0 | E77: =IFERROR(AVERAGE(E6:E76),0) -> 0 | F77: =IFERROR(AVERAGE(F6:F76),0) -> 0 | G77: =IFERROR(AVERAGE(G6:G76),0) -> 0 | H77: =IFERROR(AVERAGE(H6:H76),0) -> 0 | I77: =IFERROR(AVERAGE(I6:I76),0) -> 0 | ... M77: =IFERROR(AVERAGE(M6:M76),0) -> 0
A78: Total No. of successful students (b.) | B78: =COUNTA(B6:B76) -> 0 | C78: =COUNTA(C6:C76) -> 0 | D78: =COUNTA(D6:D76) -> 0 | E78: =COUNTA(E6:E76) -> 0 | F78: =COUNTA(F6:F76) -> 0 | G78: =COUNTA(G6:G76) -> 0 | H78: =COUNTA(H6:H76) -> 0 | I78: =COUNTA(I6:I76) -> 0 | ... M78: =COUNTA(M6:M76) -> 0
A79: Total No. of students appeared in the examination (c.)
A80: Academic Performance Index (d.) | B80: =IFERROR(B77*(B78/B79),0) -> 0 | C80: =IFERROR(C77*(C78/C79),0) -> 0 | D80: =IFERROR(D77*(D78/D79),0) -> 0 | E80: =IFERROR(E77*(E78/E79),0) -> 0 | F80: =IFERROR(F77*(F78/F79),0) -> 0 | G80: =IFERROR(G77*(G78/G79),0) -> 0 | H80: =IFERROR(H77*(H78/H79),0) -> 0 | I80: =IFERROR(I77*(I78/I79),0) -> 0 | ... M80: =IFERROR(M77*(M78/M79),0) -> 0
A81: Total No. of students above API (e.) | B81: =COUNTIF(B6:B76,">="&B80) -> 0 | C81: =COUNTIF(C6:C76,">="&C80) -> 0 | D81: =COUNTIF(D6:D76,">="&D80) -> 0 | E81: =COUNTIF(E6:E76,">="&E80) -> 0 | F81: =COUNTIF(F6:F76,">="&F80) -> 0 | G81: =COUNTIF(G6:G76,">="&G80) -> 0 | H81: =COUNTIF(H6:H76,">="&H80) -> 0 | I81: =COUNTIF(I6:I76,">="&I80) -> 0 | ... M81: =COUNTIF(M6:M76,">="&M80) -> 0
A82: Percentage of Equal and above API for individual class (f.) | B82: =IFERROR((B81/B79)*100,0) -> 0 | C82: =IFERROR((C81/C79)*100,0) -> 0 | D82: =IFERROR((D81/D79)*100,0) -> 0 | E82: =IFERROR((E81/E79)*100,0) -> 0 | F82: =IFERROR((F81/F79)*100,0) -> 0 | G82: =IFERROR((G81/G79)*100,0) -> 0 | H82: =IFERROR((H81/H79)*100,0) -> 0 | I82: =IFERROR((I81/I79)*100,0) -> 0 | ... M82: =IFERROR((M81/M79)*100,0) -> 0
A83: Toatl Average of ALL sections | B83: =IFERROR(SUM(B82:G82)/COUNTIF(B82:G82,"<>0"),0) -> 0 | H83: =IFERROR(SUM(H82:M82)/COUNTIF(H82:M82,"<>0"),0) -> 0
A84: Semester (X-2) | B84: =B83 -> 0
A85: Semester (X-1) | B85: =H83 -> 0
A86: Avg of previous two semester | B86: =AVERAGE(B84:B85) -> 0

Sheet BASE
A8: DEPARTMENT OF __________________________________
A9: THEORY CUM PRACTICAL COURSE OUTCOME ANALYSIS
A11: Name of Faculty(s) | D11: 1 | G11: 1 | J11: 1 | M11: 1 | P11: BATCH | Q11: Credit Distribution
A12: Course Code and Name | D12: 22ABXCXX | G12: XXXXXXXX XXXXX XXXXXXXX | Q12: 3T+1P | AA12: 2T+1P
A13: Branch / Year / Semester | D13: abcd | H13: 1 | L13: IV | AA13: 3T+1P
AA14: 3.5T+0.5P
A15: S.No | B15: Roll No. of Students | C15: Name of the student | E15: Target Plan
A16: 1 | B16: 23XXR001 | E16: Percentage of Marks Expected : | I16: Average Marks of Each CO | M16: Calculated Target | O16: TARGET
A17: =A16+1 -> 2 | B17: 23XXR002
A18: =A17+1 -> 3 | B18: 23XXR003 | E18: Percentage of Students Expected to attain Expected Marks: | I18: Percentage of students secured average API and above( Previous 2 semester average) | M18: =Target!B86 -> 0 | O18: =ROUND(M18+5,0) -> 5
A19: =A18+1 -> 4 | B19: 23XXR004
A20: =A19+1 -> 5 | B20: 23XXR005
A21: =A20+1 -> 6 | B21: 23XXR006
A22: =A21+1 -> 7 | B22: 23XXR007 | E22: Total No of Students enrolled in the course: | I22: =+COUNTA(B16:B476) -> 421 | J22: Number of Students Expected to attain Expected Marks: | N22: =ROUND((O18/100)*I22,0) -> 21
A23: =A22+1 -> 8 | B23: 23XXR008
A24: =A23+1 -> 9 | B24: 23XXR009
A25: =A24+1 -> 10 | B25: 23XXR010
A26: =A25+1 -> 11 | B26: 23XXR011 | E26: Course Articulation Matrix
A27: =A26+1 -> 12 | B27: 23XXR012 | E27: COs/POs | F27: PO1 | G27: PO2 | H27: PO3 | I27: PO4 | J27: PO5 | K27: PO6 | L27: PO7 | M27: PO8 | N27: PO9 | O27: PO10 | P27: PO11 | Q27: PO12 | R27: PSO1 | S27: PSO2 | V27: PO1 | W27: PO2 | X27: PO3 | Y27: PO4 | Z27: PO5 | AA27: PO6 | AB27: PO7 | AC27: PO8 | AD27: PO9 | AE27: PO10 | AF27: PO11 | AG27: PO12 | AH27: PSO1 | AI27: PSO2
A28: =A27+1 -> 13 | B28: 23XXR013 | V28: =IF(ISBLANK(F29),"","P") | W28: =IF(ISBLANK(G29),"","P") | X28: =IF(ISBLANK(H29),"","P") | Y28: =IF(ISBLANK(I29),"","P") | Z28: =IF(ISBLANK(J29),"","P") | AA28: =IF(ISBLANK(K29),"","P") | AB28: =IF(ISBLANK(L29),"","P") | AC28: =IF(ISBLANK(M29),"","P") | ... AI28: =IF(ISBLANK(S29),"","P")
A29: =A28+1 -> 14 | B29: 23XXR014 | E29: =M37 -> CO-1 | V29: =IF(ISBLANK(F30),"","P") | W29: =IF(ISBLANK(G30),"","P") | X29: =IF(ISBLANK(H30),"","P") | Y29: =IF(ISBLANK(I30),"","P") | Z29: =IF(ISBLANK(J30),"","P") | AA29: =IF(ISBLANK(K30),"","P") | AB29: =IF(ISBLANK(L30),"","P") | AC29: =IF(ISBLANK(M30),"","P") | ... AI29: =IF(ISBLANK(S30),"","P")
A30: =A29+1 -> 15 | B30: 23XXR015 | E30: =N37 -> CO-2 | V30: =IF(ISBLANK(F31),"","P") | W30: =IF(ISBLANK(G31),"","P") | X30: =IF(ISBLANK(H31),"","P") | Y30: =IF(ISBLANK(I31),"","P") | Z30: =IF(ISBLANK(J31),"","P") | AA30: =IF(ISBLANK(K31),"","P") | AB30: =IF(ISBLANK(L31),"","P") | AC30: =IF(ISBLANK(M31),"","P") | ... AI30: =IF(ISBLANK(S31),"","P")
A31: =A30+1 -> 16 | B31: 23XXR016 | E31: =O37 -> CO-3 | V31: =IF(ISBLANK(F32),"","P") | W31: =IF(ISBLANK(G32),"","P") | X31: =IF(ISBLANK(H32),"","P") | Y31: =IF(ISBLANK(I32),"","P") | Z31: =IF(ISBLANK(J32),"","P") | AA31: =IF(ISBLANK(K32),"","P") | AB31: =IF(ISBLANK(L32),"","P") | AC31: =IF(ISBLANK(M32),"","P") | ... AI31: =IF(ISBLANK(S32),"","P")
A32: =A31+1 -> 17 | B32: 23XXR017 | E32: =P37 -> CO-4 | V32: =IF(ISBLANK(F33),"","P") | W32: =IF(ISBLANK(G33),"","P") | X32: =IF(ISBLANK(H33),"","P") | Y32: =IF(ISBLANK(I33),"","P") | Z32: =IF(ISBLANK(J33),"","P") | AA32: =IF(ISBLANK(K33),"","P") | AB32: =IF(ISBLANK(L33),"","P") | AC32: =IF(ISBLANK(M33),"","P") | ... AI32: =IF(ISBLANK(S33),"","P")
A33: =A32+1 -> 18 | B33: 23XXR018 | E33: =Q37 -> CO-5 | V33: =IF(SUM(V28:V32)=0,"-",ROUND(((SUM(V28:V32))/COUNT(V28:V32)),2)) -> - | W33: =IF(SUM(W28:W32)=0,"-",ROUND(((SUM(W28:W32))/COUNT(W28:W32)),2)) -> - | X33: =IF(SUM(X28:X32)=0,"-",ROUND(((SUM(X28:X32))/COUNT(X28:X32)),2)) -> - | Y33: =IF(SUM(Y28:Y32)=0,"-",ROUND(((SUM(Y28:Y32))/COUNT(Y28:Y32)),2)) -> - | Z33: =IF(SUM(Z28:Z32)=0,"-",ROUND(((SUM(Z28:Z32))/COUNT(Z28:Z32)),2)) -> - | AA33: =IF(SUM(AA28:AA32)=0,"-",ROUND(((SUM(AA28:AA32))/COUNT(AA28:AA32)),2)) -> - | AB33: =IF(SUM(AB28:AB32)=0,"-",ROUND(((SUM(AB28:AB32))/COUNT(AB28:AB32)),2)) -> - | AC33: =IF(SUM(AC28:AC32)=0,"-",ROUND(((SUM(AC28:AC32))/COUNT(AC28:AC32)),2)) -> - | ... AI33: =IF(SUM(AI28:AI32)=0,"-",ROUND(((SUM(AI28:AI32))/COUNT(AI28:AI32)),2)) -> -
A34: =A33+1 -> 19 | B34: 23XXR019 | E34: Avg | F34: =IF(SUM(F29:F33)=0,"-",ROUND(((SUM(F29:F33))/COUNT(F29:F33)),2)) -> - | G34: =IF(SUM(G29:G33)=0,"-",ROUND(((SUM(G29:G33))/COUNT(G29:G33)),2)) -> - | H34: =IF(SUM(H29:H33)=0,"-",ROUND(((SUM(H29:H33))/COUNT(H29:H33)),2)) -> - | I34: =IF(SUM(I29:I33)=0,"-",ROUND(((SUM(I29:I33))/COUNT(I29:I33)),2)) -> - | J34: =IF(SUM(J29:J33)=0,"-",ROUND(((SUM(J29:J33))/COUNT(J29:J33)),2)) -> - | K34: =IF(SUM(K29:K33)=0,"-",ROUND(((SUM(K29:K33))/COUNT(K29:K33)),2)) -> - | L34: =IF(SUM(L29:L33)=0,"-",ROUND(((SUM(L29:L33))/COUNT(L29:L33)),2)) -> - | M34: =IF(SUM(M29:M33)=0,"-",ROUND(((SUM(M29:M33))/COUNT(M29:M33)),2)) -> - | ... S34: =IF(SUM(S29:S33)=0,"-",ROUND(((SUM(S29:S33))/COUNT(S29:S33)),2)) -> -
A35: =A34+1 -> 20 | B35: 23XXR020
A36: =A35+1 -> 21 | B36: 23XXR021 | G36: CO ATTAINMENT:
A37: =A36+1 -> 22 | B37: 23XXR022 | G37: Course Outcomes | M37: CO-1 | N37: CO-2 | O37: CO-3 | P37: CO-4 | Q37: CO-5
A38: =A37+1 -> 23 | B38: 23XXR023 | G38: Continuous Assessment Based Analysis (%) | M38: ='Internal CO'!C465 -> 0 | N38: ='Internal CO'!D465 -> 0 | O38: ='Internal CO'!E465 -> 0 | P38: ='Internal CO'!F465 -> 0 | Q38: ='Internal CO'!G465 -> 0
A39: =A38+1 -> 24 | B39: 23XXR024 | G39: End Semester Exam Based Analysis (%) | M39: ='ESE CO'!C464 -> 0 | N39: ='ESE CO'!D464 -> 0 | O39: ='ESE CO'!E464 -> 0 | P39: ='ESE CO'!F464 -> 0 | Q39: ='ESE CO'!G464 -> 0
A40: =A39+1 -> 25 | B40: 23XXR025 | G40: Overall Attainment (50% Internal + 50% ESE) | M40: =IFERROR(M38*0.5+M39*0.5,"") -> 0 | N40: =IFERROR(N38*0.5+N39*0.5,"") -> 0 | O40: =IFERROR(O38*0.5+O39*0.5,"") -> 0 | P40: =IFERROR(P38*0.5+P39*0.5,"") -> 0 | Q40: =IFERROR(Q38*0.5+Q39*0.5,"") -> 0
A41: =A40+1 -> 26 | B41: 23XXR026
A42: =A41+1 -> 27 | B42: 23XXR027 | E42: PO ATTAINMENT
A43: =A42+1 -> 28 | B43: 23XXR028 | E43: COs/POs | F43: PO1 | G43: PO2 | H43: PO3 | I43: PO4 | J43: PO5 | K43: PO6 | L43: PO7 | M43: PO8 | N43: PO9 | O43: PO10 | P43: PO11 | Q43: PO12 | R43: PSO1 | S43: PSO2
A44: =A43+1 -> 29 | B44: 23XXR029 | E44: =+E29 -> CO-1 | F44: =IF(V28="P",(F29*($M$40/100)),"-") -> - | G44: =IF(W28="P",(G29*($M$40/100)),"-") -> - | H44: =IF(X28="P",(H29*($M$40/100)),"-") -> - | I44: =IF(Y28="P",(I29*($M$40/100)),"-") -> - | J44: =IF(Z28="P",(J29*($M$40/100)),"-") -> - | K44: =IF(AA28="P",(K29*($M$40/100)),"-") -> - | L44: =IF(AB28="P",(L29*($M$40/100)),"-") -> - | M44: =IF(AC28="P",(M29*($M$40/100)),"-") -> - | ... S44: =IF(AI28="P",(S29*($M$40/100)),"-") -> -
A45: =A44+1 -> 30 | B45: 23XXR030 | E45: =+E30 -> CO-2 | F45: =IF(V29="P",(F30*($N$40/100)),"-") -> - | G45: =IF(W29="P",(G30*($N$40/100)),"-") -> - | H45: =IF(X29="P",(H30*($N$40/100)),"-") -> - | I45: =IF(Y29="P",(I30*($N$40/100)),"-") -> - | J45: =IF(Z29="P",(J30*($N$40/100)),"-") -> - | K45: =IF(AA29="P",(K30*($N$40/100)),"-") -> - | L45: =IF(AB29="P",(L30*($N$40/100)),"-") -> - | M45: =IF(AC29="P",(M30*($N$40/100)),"-") -> - | ... S45: =IF(AI29="P",(S30*($N$40/100)),"-") -> -
A46: =A45+1 -> 31 | B46: 23XXR031 | E46: =+E31 -> CO-3 | F46: =IF(V30="P",(F31*($O$40/100)),"-") -> - | G46: =IF(W30="P",(G31*($O$40/100)),"-") -> - | H46: =IF(X30="P",(H31*($O$40/100)),"-") -> - | I46: =IF(Y30="P",(I31*($O$40/100)),"-") -> - | J46: =IF(Z30="P",(J31*($O$40/100)),"-") -> - | K46: =IF(AA30="P",(K31*($O$40/100)),"-") -> - | L46: =IF(AB30="P",(L31*($O$40/100)),"-") -> - | M46: =IF(AC30="P",(M31*($O$40/100)),"-") -> - | ... S46: =IF(AI30="P",(S31*($O$40/100)),"-") -> -
A47: =A46+1 -> 32 | B47: 23XXR032 | E47: =+E32 -> CO-4 | F47: =IF(V31="P",(F32*($P$40/100)),"-") -> - | G47: =IF(W31="P",(G32*($P$40/100)),"-") -> - | H47: =IF(X31="P",(H32*($P$40/100)),"-") -> - | I47: =IF(Y31="P",(I32*($P$40/100)),"-") -> - | J47: =IF(Z31="P",(J32*($P$40/100)),"-") -> - | K47: =IF(AA31="P",(K32*($P$40/100)),"-") -> - | L47: =IF(AB31="P",(L32*($P$40/100)),"-") -> - | M47: =IF(AC31="P",(M32*($P$40/100)),"-") -> - | ... S47: =IF(AI31="P",(S32*($P$40/100)),"-") -> -
A48: =A47+1 -> 33 | B48: 23XXR033 | E48: =+E33 -> CO-5 | F48: =IF(V32="P",(F33*($Q$40/100)),"-") -> - | G48: =IF(W32="P",(G33*($Q$40/100)),"-") -> - | H48: =IF(X32="P",(H33*($Q$40/100)),"-") -> - | I48: =IF(Y32="P",(I33*($Q$40/100)),"-") -> - | J48: =IF(Z32="P",(J33*($Q$40/100)),"-") -> - | K48: =IF(AA32="P",(K33*($Q$40/100)),"-") -> - | L48: =IF(AB32="P",(L33*($Q$40/100)),"-") -> - | M48: =IF(AC32="P",(M33*($Q$40/100)),"-") -> - | ... S48: =IF(AI32="P",(S33*($Q$40/100)),"-") -> -
...

Sheet CAT-1
A1: =BASE!A7 -> 0 | S1: =BASE!A7 -> 0
A2: =+BASE!A8 -> DEPARTMENT OF __________________________________ | S2: =BASE!A8 -> DEPARTMENT OF __________________________________
A3: =+BASE!A9 -> THEORY CUM PRACTICAL COURSE OUTCOME ANALYSIS | S3: =BASE!A9 -> THEORY CUM PRACTICAL COURSE OUTCOME ANALYSIS
A4: =BASE!A11 -> Name of Faculty(s) | B4: : | C4: =BASE!D11 -> 1 | G4: =BASE!G11 -> 1 | K4: =BASE!J11 -> 1 | O4: =BASE!M11 -> 1 | S4: Course Code | U4: =BASE!D12 -> 22ABXCXX
A5: =BASE!A12 -> Course Code and Name | B5: : | C5: =BASE!D12 -> 22ABXCXX | G5: =BASE!G12 -> XXXXXXXX XXXXX XXXXXXXX | S5: Course Name | U5: =BASE!G12 -> XXXXXXXX XXXXX XXXXXXXX
A6: =BASE!A13 -> Branch / Year / Semester | B6: : | C6: =+BASE!D13 -> abcd | G6: =BASE!H13 -> 1 | I6: =BASE!L13 -> IV | K6: Date | N6: : | S6: =BASE!A13 -> Branch / Year / Semester | U6: =BASE!D13 -> abcd | W6: =BASE!H13 -> 1 | X6: =BASE!L13 -> IV
A7: Continuous Assessment Test | B7: : | C7: I | G7: Total No. of Students | K7: : | L7: =ROWS(A12:A480)-COUNTIF(A12:A480,"") -> 421 | O7: Max marks | Q7: : | S7: =A7 -> Continuous Assessment Test | U7: =C7 -> I
A9: Roll No | B9: Q. Nos | C9: 1 | D9: 2 | E9: 3 | F9: 4 | G9: 5 | H9: 6 | I9: 7 | J9: 8 | K9: 9 | L9: 10 | M9: 11 | N9: 12 | O9: 13 | P9: 14 | R9: TOT MARKS | S9: S.NO | T9: CO1 | U9: CO2 | V9: CO3 | W9: CO4 | X9: CO5
B10: Max Marks | C10: 2 | D10: 2 | E10: 2 | F10: 2 | G10: 2 | H10: 2 | I10: 2 | J10: 2 | K10: 2 | L10: 2 | M10: 10 | N10: 10 | O10: 10 | P10: 10 | T10: =SUMIF($C$11:$Q$11,1,C10:Q10) -> 42 | U10: =SUMIF($C$11:$Q$11,2,C10:Q10) -> 18 | V10: =SUMIF($C$11:$Q$11,3,C10:Q10) -> 0 | W10: =SUMIF($C$11:$Q$11,4,C10:Q10) -> 0 | X10: =SUMIF($C$11:$Q$11,5,C10:Q10) -> 0
B11: COs | C11: 1 | D11: 1 | E11: 1 | F11: 1 | G11: 1 | H11: 1 | I11: 2 | J11: 2 | K11: 2 | L11: 2 | M11: 1 | N11: 1 | O11: 1 | P11: 2
A12: =IF(BASE!B16="","",BASE!B16) -> 23XXR001 | B12: : | R12: =SUM(C12:Q12) -> 0 | S12: =BASE!A16 -> 1 | T12: =SUMIF($C$11:$Q$11,1,C12:Q12) -> 0 | U12: =SUMIF($C$11:$Q$11,2,C12:Q12) -> 0 | V12: =SUMIF($C$11:$Q$11,3,C12:Q12) -> 0 | W12: =SUMIF($C$11:$Q$11,4,C12:Q12) -> 0 | X12: =SUMIF($C$11:$Q$11,5,C12:Q12) -> 0
A13: =IF(BASE!B17="","",BASE!B17) -> 23XXR002 | B13: : | R13: =SUM(C13:Q13) -> 0 | S13: =BASE!A17 -> 2 | T13: =SUMIF($C$11:$Q$11,1,C13:Q13) -> 0 | U13: =SUMIF($C$11:$Q$11,2,C13:Q13) -> 0 | V13: =SUMIF($C$11:$Q$11,3,C13:Q13) -> 0 | W13: =SUMIF($C$11:$Q$11,4,C13:Q13) -> 0 | X13: =SUMIF($C$11:$Q$11,5,C13:Q13) -> 0
A14: =IF(BASE!B18="","",BASE!B18) -> 23XXR003 | B14: : | R14: =SUM(C14:Q14) -> 0 | S14: =BASE!A18 -> 3 | T14: =SUMIF($C$11:$Q$11,1,C14:Q14) -> 0 | U14: =SUMIF($C$11:$Q$11,2,C14:Q14) -> 0 | V14: =SUMIF($C$11:$Q$11,3,C14:Q14) -> 0 | W14: =SUMIF($C$11:$Q$11,4,C14:Q14) -> 0 | X14: =SUMIF($C$11:$Q$11,5,C14:Q14) -> 0
A15: =IF(BASE!B19="","",BASE!B19) -> 23XXR004 | B15: : | R15: =SUM(C15:Q15) -> 0 | S15: =BASE!A19 -> 4 | T15: =SUMIF($C$11:$Q$11,1,C15:Q15) -> 0 | U15: =SUMIF($C$11:$Q$11,2,C15:Q15) -> 0 | V15: =SUMIF($C$11:$Q$11,3,C15:Q15) -> 0 | W15: =SUMIF($C$11:$Q$11,4,C15:Q15) -> 0 | X15: =SUMIF($C$11:$Q$11,5,C15:Q15) -> 0
A16: =IF(BASE!B20="","",BASE!B20) -> 23XXR005 | B16: : | R16: =SUM(C16:Q16) -> 0 | S16: =BASE!A20 -> 5 | T16: =SUMIF($C$11:$Q$11,1,C16:Q16) -> 0 | U16: =SUMIF($C$11:$Q$11,2,C16:Q16) -> 0 | V16: =SUMIF($C$11:$Q$11,3,C16:Q16) -> 0 | W16: =SUMIF($C$11:$Q$11,4,C16:Q16) -> 0 | X16: =SUMIF($C$11:$Q$11,5,C16:Q16) -> 0
A17: =IF(BASE!B21="","",BASE!B21) -> 23XXR006 | B17: : | R17: =SUM(C17:Q17) -> 0 | S17: =BASE!A21 -> 6 | T17: =SUMIF($C$11:$Q$11,1,C17:Q17) -> 0 | U17: =SUMIF($C$11:$Q$11,2,C17:Q17) -> 0 | V17: =SUMIF($C$11:$Q$11,3,C17:Q17) -> 0 | W17: =SUMIF($C$11:$Q$11,4,C17:Q17) -> 0 | X17: =SUMIF($C$11:$Q$11,5,C17:Q17) -> 0
A18: =IF(BASE!B22="","",BASE!B22) -> 23XXR007 | B18: : | R18: =SUM(C18:Q18) -> 0 | S18: =BASE!A22 -> 7 | T18: =SUMIF($C$11:$Q$11,1,C18:Q18) -> 0 | U18: =SUMIF($C$11:$Q$11,2,C18:Q18) -> 0 | V18: =SUMIF($C$11:$Q$11,3,C18:Q18) -> 0 | W18: =SUMIF($C$11:$Q$11,4,C18:Q18) -> 0 | X18: =SUMIF($C$11:$Q$11,5,C18:Q18) -> 0
A19: =IF(BASE!B23="","",BASE!B23) -> 23XXR008 | B19: : | R19: =SUM(C19:Q19) -> 0 | S19: =BASE!A23 -> 8 | T19: =SUMIF($C$11:$Q$11,1,C19:Q19) -> 0 | U19: =SUMIF($C$11:$Q$11,2,C19:Q19) -> 0 | V19: =SUMIF($C$11:$Q$11,3,C19:Q19) -> 0 | W19: =SUMIF($C$11:$Q$11,4,C19:Q19) -> 0 | X19: =SUMIF($C$11:$Q$11,5,C19:Q19) -> 0
A20: =IF(BASE!B24="","",BASE!B24) -> 23XXR009 | B20: : | R20: =SUM(C20:Q20) -> 0 | S20: =BASE!A24 -> 9 | T20: =SUMIF($C$11:$Q$11,1,C20:Q20) -> 0 | U20: =SUMIF($C$11:$Q$11,2,C20:Q20) -> 0 | V20: =SUMIF($C$11:$Q$11,3,C20:Q20) -> 0 | W20: =SUMIF($C$11:$Q$11,4,C20:Q20) -> 0 | X20: =SUMIF($C$11:$Q$11,5,C20:Q20) -> 0
A21: =IF(BASE!B25="","",BASE!B25) -> 23XXR010 | B21: : | R21: =SUM(C21:Q21) -> 0 | S21: =BASE!A25 -> 10 | T21: =SUMIF($C$11:$Q$11,1,C21:Q21) -> 0 | U21: =SUMIF($C$11:$Q$11,2,C21:Q21) -> 0 | V21: =SUMIF($C$11:$Q$11,3,C21:Q21) -> 0 | W21: =SUMIF($C$11:$Q$11,4,C21:Q21) -> 0 | X21: =SUMIF($C$11:$Q$11,5,C21:Q21) -> 0
A22: =IF(BASE!B26="","",BASE!B26) -> 23XXR011 | B22: : | R22: =SUM(C22:Q22) -> 0 | S22: =BASE!A26 -> 11 | T22: =SUMIF($C$11:$Q$11,1,C22:Q22) -> 0 | U22: =SUMIF($C$11:$Q$11,2,C22:Q22) -> 0 | V22: =SUMIF($C$11:$Q$11,3,C22:Q22) -> 0 | W22: =SUMIF($C$11:$Q$11,4,C22:Q22) -> 0 | X22: =SUMIF($C$11:$Q$11,5,C22:Q22) -> 0
A23: =IF(BASE!B27="","",BASE!B27) -> 23XXR012 | B23: : | R23: =SUM(C23:Q23) -> 0 | S23: =BASE!A27 -> 12 | T23: =SUMIF($C$11:$Q$11,1,C23:Q23) -> 0 | U23: =SUMIF($C$11:$Q$11,2,C23:Q23) -> 0 | V23: =SUMIF($C$11:$Q$11,3,C23:Q23) -> 0 | W23: =SUMIF($C$11:$Q$11,4,C23:Q23) -> 0 | X23: =SUMIF($C$11:$Q$11,5,C23:Q23) -> 0
... A461: =IF(BASE!B465="","",BASE!B465) | B461: : | R461: =SUM(C461:Q461) -> 0 | S461: =BASE!A465 -> 450 | T461: =SUMIF($C$11:$Q$11,1,C461:Q461) -> 0 | U461: =SUMIF($C$11:$Q$11,2,C461:Q461) -> 0 | V461: =SUMIF($C$11:$Q$11,3,C461:Q461) -> 0 | W461: =SUMIF($C$11:$Q$11,4,C461:Q461) -> 0 | X461: =SUMIF($C$11:$Q$11,5,C461:Q461) -> 0

Sheet CAT- 2
A1: =BASE!A7 -> 0 | S1: =BASE!A7 -> 0
A2: =+BASE!A8 -> DEPARTMENT OF __________________________________ | S2: =BASE!A8 -> DEPARTMENT OF __________________________________
A3: =+BASE!A9 -> THEORY CUM PRACTICAL COURSE OUTCOME ANALYSIS | S3: =BASE!A9 -> THEORY CUM PRACTICAL COURSE OUTCOME ANALYSIS
A4: =BASE!A11 -> Name of Faculty(s) | B4: : | C4: =BASE!D11 -> 1 | G4: =BASE!G11 -> 1 | K4: =BASE!J11 -> 1 | O4: =BASE!M11 -> 1 | S4: Course Code | U4: =BASE!D12 -> 22ABXCXX
A5: =BASE!A12 -> Course Code and Name | B5: : | C5: =BASE!D12 -> 22ABXCXX | G5: =BASE!G12 -> XXXXXXXX XXXXX XXXXXXXX | S5: Course Name | U5: =BASE!G12 -> XXXXXXXX XXXXX XXXXXXXX
A6: =BASE!A13 -> Branch / Year / Semester | B6: : | C6: =+BASE!D13 -> abcd | G6: =BASE!H13 -> 1 | I6: =BASE!L13 -> IV | K6: Date | N6: : | S6: =BASE!A13 -> Branch / Year / Semester | U6: =BASE!D13 -> abcd | W6: =BASE!H13 -> 1 | X6: =BASE!L13 -> IV
A7: Continuous Assessment Test | B7: : | C7: II | G7: Total No. of Students | K7: : | L7: =ROWS(A12:A480)-COUNTIF(A12:A480,"") -> 421 | O7: Max marks | Q7: : | S7: =A7 -> Continuous Assessment Test | U7: II
A9: Roll No | B9: Q. Nos | C9: 1 | D9: 2 | E9: 3 | F9: 4 | G9: 5 | H9: 6 | I9: 7 | J9: 8 | K9: 9 | L9: 10 | M9: 11 | N9: 12 | O9: 13 | P9: 14 | R9: TOT MARKS | S9: S.NO | T9: CO1 | U9: CO2 | V9: CO3 | W9: CO4 | X9: CO5
B10: Max Marks | C10: 2 | D10: 2 | E10: 2 | F10: 2 | G10: 2 | H10: 2 | I10: 2 | J10: 2 | K10: 2 | L10: 2 | M10: 10 | N10: 10 | O10: 10 | P10: 10 | T10: =SUMIF($C$11:$Q$11,1,C10:Q10) -> 0 | U10: =SUMIF($C$11:$Q$11,2,C10:Q10) -> 28 | V10: =SUMIF($C$11:$Q$11,3,C10:Q10) -> 32 | W10: =SUMIF($C$11:$Q$11,4,C10:Q10) -> 0 | X10: =SUMIF($C$11:$Q$11,5,C10:Q10) -> 0
B11: COs | C11: 2 | D11: 2 | E11: 2 | F11: 2 | G11: 3 | H11: 3 | I11: 3 | J11: 3 | K11: 3 | L11: 3 | M11: 2 | N11: 2 | O11: 3 | P11: 3
A12: =+IF(BASE!B16="","",BASE!B16) -> 23XXR001 | B12: : | R12: =SUM(C12:Q12) -> 0 | S12: =BASE!A16 -> 1 | T12: =SUMIF($C$11:$Q$11,1,C12:Q12) -> 0 | U12: =SUMIF($C$11:$Q$11,2,C12:Q12) -> 0 | V12: =SUMIF($C$11:$Q$11,3,C12:Q12) -> 0 | W12: =SUMIF($C$11:$Q$11,4,C12:Q12) -> 0 | X12: =SUMIF($C$11:$Q$11,5,C12:Q12) -> 0
A13: =+IF(BASE!B17="","",BASE!B17) -> 23XXR002 | B13: : | R13: =SUM(C13:Q13) -> 0 | S13: =BASE!A17 -> 2 | T13: =SUMIF($C$11:$Q$11,1,C13:Q13) -> 0 | U13: =SUMIF($C$11:$Q$11,2,C13:Q13) -> 0 | V13: =SUMIF($C$11:$Q$11,3,C13:Q13) -> 0 | W13: =SUMIF($C$11:$Q$11,4,C13:Q13) -> 0 | X13: =SUMIF($C$11:$Q$11,5,C13:Q13) -> 0
A14: =+IF(BASE!B18="","",BASE!B18) -> 23XXR003 | B14: : | R14: =SUM(C14:Q14) -> 0 | S14: =BASE!A18 -> 3 | T14: =SUMIF($C$11:$Q$11,1,C14:Q14) -> 0 | U14: =SUMIF($C$11:$Q$11,2,C14:Q14) -> 0 | V14: =SUMIF($C$11:$Q$11,3,C14:Q14) -> 0 | W14: =SUMIF($C$11:$Q$11,4,C14:Q14) -> 0 | X14: =SUMIF($C$11:$Q$11,5,C14:Q14) -> 0
A15: =+IF(BASE!B19="","",BASE!B19) -> 23XXR004 | B15: : | R15: =SUM(C15:Q15) -> 0 | S15: =BASE!A19 -> 4 | T15: =SUMIF($C$11:$Q$11,1,C15:Q15) -> 0 | U15: =SUMIF($C$11:$Q$11,2,C15:Q15) -> 0 | V15: =SUMIF($C$11:$Q$11,3,C15:Q15) -> 0 | W15: =SUMIF($C$11:$Q$11,4,C15:Q15) -> 0 | X15: =SUMIF($C$11:$Q$11,5,C15:Q15) -> 0
A16: =+IF(BASE!B20="","",BASE!B20) -> 23XXR005 | B16: : | R16: =SUM(C16:Q16) -> 0 | S16: =BASE!A20 -> 5 | T16: =SUMIF($C$11:$Q$11,1,C16:Q16) -> 0 | U16: =SUMIF($C$11:$Q$11,2,C16:Q16) -> 0 | V16: =SUMIF($C$11:$Q$11,3,C16:Q16) -> 0 | W16: =SUMIF($C$11:$Q$11,4,C16:Q16) -> 0 | X16: =SUMIF($C$11:$Q$11,5,C16:Q16) -> 0
A17: =+IF(BASE!B21="","",BASE!B21) -> 23XXR006 | B17: : | R17: =SUM(C17:Q17) -> 0 | S17: =BASE!A21 -> 6 | T17: =SUMIF($C$11:$Q$11,1,C17:Q17) -> 0 | U17: =SUMIF($C$11:$Q$11,2,C17:Q17) -> 0 | V17: =SUMIF($C$11:$Q$11,3,C17:Q17) -> 0 | W17: =SUMIF($C$11:$Q$11,4,C17:Q17) -> 0 | X17: =SUMIF($C$11:$Q$11,5,C17:Q17) -> 0
A18: =+IF(BASE!B22="","",BASE!B22) -> 23XXR007 | B18: : | R18: =SUM(C18:Q18) -> 0 | S18: =BASE!A22 -> 7 | T18: =SUMIF($C$11:$Q$11,1,C18:Q18) -> 0 | U18: =SUMIF($C$11:$Q$11,2,C18:Q18) -> 0 | V18: =SUMIF($C$11:$Q$11,3,C18:Q18) -> 0 | W18: =SUMIF($C$11:$Q$11,4,C18:Q18) -> 0 | X18: =SUMIF($C$11:$Q$11,5,C18:Q18) -> 0
A19: =+IF(BASE!B23="","",BASE!B23) -> 23XXR008 | B19: : | R19: =SUM(C19:Q19) -> 0 | S19: =BASE!A23 -> 8 | T19: =SUMIF($C$11:$Q$11,1,C19:Q19) -> 0 | U19: =SUMIF($C$11:$Q$11,2,C19:Q19) -> 0 | V19: =SUMIF($C$11:$Q$11,3,C19:Q19) -> 0 | W19: =SUMIF($C$11:$Q$11,4,C19:Q19) -> 0 | X19: =SUMIF($C$11:$Q$11,5,C19:Q19) -> 0
A20: =+IF(BASE!B24="","",BASE!B24) -> 23XXR009 | B20: : | R20: =SUM(C20:Q20) -> 0 | S20: =BASE!A24 -> 9 | T20: =SUMIF($C$11:$Q$11,1,C20:Q20) -> 0 | U20: =SUMIF($C$11:$Q$11,2,C20:Q20) -> 0 | V20: =SUMIF($C$11:$Q$11,3,C20:Q20) -> 0 | W20: =SUMIF($C$11:$Q$11,4,C20:Q20) -> 0 | X20: =SUMIF($C$11:$Q$11,5,C20:Q20) -> 0
A21: =+IF(BASE!B25="","",BASE!B25) -> 23XXR010 | B21: : | R21: =SUM(C21:Q21) -> 0 | S21: =BASE!A25 -> 10 | T21: =SUMIF($C$11:$Q$11,1,C21:Q21) -> 0 | U21: =SUMIF($C$11:$Q$11,2,C21:Q21) -> 0 | V21: =SUMIF($C$11:$Q$11,3,C21:Q21) -> 0 | W21: =SUMIF($C$11:$Q$11,4,C21:Q21) -> 0 | X21: =SUMIF($C$11:$Q$11,5,C21:Q21) -> 0
A22: =+IF(BASE!B26="","",BASE!B26) -> 23XXR011 | B22: : | R22: =SUM(C22:Q22) -> 0 | S22: =BASE!A26 -> 11 | T22: =SUMIF($C$11:$Q$11,1,C22:Q22) -> 0 | U22: =SUMIF($C$11:$Q$11,2,C22:Q22) -> 0 | V22: =SUMIF($C$11:$Q$11,3,C22:Q22) -> 0 | W22: =SUMIF($C$11:$Q$11,4,C22:Q22) -> 0 | X22: =SUMIF($C$11:$Q$11,5,C22:Q22) -> 0
A23: =+IF(BASE!B27="","",BASE!B27) -> 23XXR012 | B23: : | R23: =SUM(C23:Q23) -> 0 | S23: =BASE!A27 -> 12 | T23: =SUMIF($C$11:$Q$11,1,C23:Q23) -> 0 | U23: =SUMIF($C$11:$Q$11,2,C23:Q23) -> 0 | V23: =SUMIF($C$11:$Q$11,3,C23:Q23) -> 0 | W23: =SUMIF($C$11:$Q$11,4,C23:Q23) -> 0 | X23: =SUMIF($C$11:$Q$11,5,C23:Q23) -> 0
... A461: =+IF(BASE!B465="","",BASE!B465) | B461: : | R461: =SUM(C461:Q461) -> 0 | S461: =BASE!A465 -> 450 | T461: =SUMIF($C$11:$Q$11,1,C461:Q461) -> 0 | U461: =SUMIF($C$11:$Q$11,2,C461:Q461) -> 0 | V461: =SUMIF($C$11:$Q$11,3,C461:Q461) -> 0 | W461: =SUMIF($C$11:$Q$11,4,C461:Q461) -> 0 | X461: =SUMIF($C$11:$Q$11,5,C461:Q461) -> 0

Sheet CAT-3
A1: =BASE!A7 -> 0 | S1: =BASE!A7 -> 0
A2: =+BASE!A8 -> DEPARTMENT OF __________________________________ | S2: =BASE!A8 -> DEPARTMENT OF __________________________________
A3: =+BASE!A9 -> THEORY CUM PRACTICAL COURSE OUTCOME ANALYSIS | S3: =BASE!A9 -> THEORY CUM PRACTICAL COURSE OUTCOME ANALYSIS
A4: =BASE!A11 -> Name of Faculty(s) | B4: : | C4: =BASE!D11 -> 1 | G4: =BASE!G11 -> 1 | K4: =BASE!J11 -> 1 | O4: =BASE!M11 -> 1 | S4: Course Code | U4: =BASE!D12 -> 22ABXCXX
A5: =BASE!A12 -> Course Code and Name | B5: : | C5: =BASE!D12 -> 22ABXCXX | G5: =BASE!G12 -> XXXXXXXX XXXXX XXXXXXXX | S5: Course Name | U5: =BASE!G12 -> XXXXXXXX XXXXX XXXXXXXX
A6: =BASE!A13 -> Branch / Year / Semester | B6: : | C6: =+BASE!D13 -> abcd | G6: =BASE!H13 -> 1 | I6: =BASE!L13 -> IV | K6: Date | N6: : | S6: =BASE!A13 -> Branch / Year / Semester | U6: =BASE!D13 -> abcd | W6: =BASE!H13 -> 1 | X6: =BASE!L13 -> IV
A7: Continuous Assessment Test | B7: : | C7: III | G7: Total No. of Students | K7: : | L7: =ROWS(A12:A480)-COUNTIF(A12:A480,"") -> 421 | O7: Max marks | Q7: : | S7: =A7 -> Continuous Assessment Test | U7: =C7 -> III
A9: Roll No | B9: Q. Nos | C9: 1 | D9: 2 | E9: 3 | F9: 4 | G9: 5 | H9: 6 | I9: 7 | J9: 8 | K9: 9 | L9: 10 | M9: 11 | N9: 12 | O9: 13 | P9: 14 | R9: TOT MARKS | S9: S.NO | T9: CO1 | U9: CO2 | V9: CO3 | W9: CO4 | X9: CO5
B10: Max Marks | C10: 2 | D10: 2 | E10: 2 | F10: 2 | G10: 2 | H10: 2 | I10: 2 | J10: 2 | K10: 2 | L10: 2 | M10: 10 | N10: 10 | O10: 10 | P10: 10 | T10: =SUMIF($C$11:$Q$11,1,C10:Q10) -> 0 | U10: =SUMIF($C$11:$Q$11,2,C10:Q10) -> 0 | V10: =SUMIF($C$11:$Q$11,3,C10:Q10) -> 0 | W10: =SUMIF($C$11:$Q$11,4,C10:Q10) -> 30 | X10: =SUMIF($C$11:$Q$11,5,C10:Q10) -> 30
B11: COs | C11: 4 | D11: 4 | E11: 4 | F11: 4 | G11: 4 | H11: 5 | I11: 5 | J11: 5 | K11: 5 | L11: 5 | M11: 4 | N11: 4 | O11: 5 | P11: 5
A12: =+IF(BASE!B16="","",BASE!B16) -> 23XXR001 | B12: : | R12: =SUM(C12:Q12) -> 0 | S12: =BASE!A16 -> 1 | T12: =SUMIF($C$11:$Q$11,1,C12:Q12) -> 0 | U12: =SUMIF($C$11:$Q$11,2,C12:Q12) -> 0 | V12: =SUMIF($C$11:$Q$11,3,C12:Q12) -> 0 | W12: =SUMIF($C$11:$Q$11,4,C12:Q12) -> 0 | X12: =SUMIF($C$11:$Q$11,5,C12:Q12) -> 0
A13: =+IF(BASE!B17="","",BASE!B17) -> 23XXR002 | B13: : | R13: =SUM(C13:Q13) -> 0 | S13: =BASE!A17 -> 2 | T13: =SUMIF($C$11:$Q$11,1,C13:Q13) -> 0 | U13: =SUMIF($C$11:$Q$11,2,C13:Q13) -> 0 | V13: =SUMIF($C$11:$Q$11,3,C13:Q13) -> 0 | W13: =SUMIF($C$11:$Q$11,4,C13:Q13) -> 0 | X13: =SUMIF($C$11:$Q$11,5,C13:Q13) -> 0
A14: =+IF(BASE!B18="","",BASE!B18) -> 23XXR003 | B14: : | R14: =SUM(C14:Q14) -> 0 | S14: =BASE!A18 -> 3 | T14: =SUMIF($C$11:$Q$11,1,C14:Q14) -> 0 | U14: =SUMIF($C$11:$Q$11,2,C14:Q14) -> 0 | V14: =SUMIF($C$11:$Q$11,3,C14:Q14) -> 0 | W14: =SUMIF($C$11:$Q$11,4,C14:Q14) -> 0 | X14: =SUMIF($C$11:$Q$11,5,C14:Q14) -> 0
A15: =+IF(BASE!B19="","",BASE!B19) -> 23XXR004 | B15: : | R15: =SUM(C15:Q15) -> 0 | S15: =BASE!A19 -> 4 | T15: =SUMIF($C$11:$Q$11,1,C15:Q15) -> 0 | U15: =SUMIF($C$11:$Q$11,2,C15:Q15) -> 0 | V15: =SUMIF($C$11:$Q$11,3,C15:Q15) -> 0 | W15: =SUMIF($C$11:$Q$11,4,C15:Q15) -> 0 | X15: =SUMIF($C$11:$Q$11,5,C15:Q15) -> 0
A16: =+IF(BASE!B20="","",BASE!B20) -> 23XXR005 | B16: : | R16: =SUM(C16:Q16) -> 0 | S16: =BASE!A20 -> 5 | T16: =SUMIF($C$11:$Q$11,1,C16:Q16) -> 0 | U16: =SUMIF($C$11:$Q$11,2,C16:Q16) -> 0 | V16: =SUMIF($C$11:$Q$11,3,C16:Q16) -> 0 | W16: =SUMIF($C$11:$Q$11,4,C16:Q16) -> 0 | X16: =SUMIF($C$11:$Q$11,5,C16:Q16) -> 0
A17: =+IF(BASE!B21="","",BASE!B21) -> 23XXR006 | B17: : | R17: =SUM(C17:Q17) -> 0 | S17: =BASE!A21 -> 6 | T17: =SUMIF($C$11:$Q$11,1,C17:Q17) -> 0 | U17: =SUMIF($C$11:$Q$11,2,C17:Q17) -> 0 | V17: =SUMIF($C$11:$Q$11,3,C17:Q17) -> 0 | W17: =SUMIF($C$11:$Q$11,4,C17:Q17) -> 0 | X17: =SUMIF($C$11:$Q$11,5,C17:Q17) -> 0
A18: =+IF(BASE!B22="","",BASE!B22) -> 23XXR007 | B18: : | R18: =SUM(C18:Q18) -> 0 | S18: =BASE!A22 -> 7 | T18: =SUMIF($C$11:$Q$11,1,C18:Q18) -> 0 | U18: =SUMIF($C$11:$Q$11,2,C18:Q18) -> 0 | V18: =SUMIF($C$11:$Q$11,3,C18:Q18) -> 0 | W18: =SUMIF($C$11:$Q$11,4,C18:Q18) -> 0 | X18: =SUMIF($C$11:$Q$11,5,C18:Q18) -> 0
A19: =+IF(BASE!B23="","",BASE!B23) -> 23XXR008 | B19: : | R19: =SUM(C19:Q19) -> 0 | S19: =BASE!A23 -> 8 | T19: =SUMIF($C$11:$Q$11,1,C19:Q19) -> 0 | U19: =SUMIF($C$11:$Q$11,2,C19:Q19) -> 0 | V19: =SUMIF($C$11:$Q$11,3,C19:Q19) -> 0 | W19: =SUMIF($C$11:$Q$11,4,C19:Q19) -> 0 | X19: =SUMIF($C$11:$Q$11,5,C19:Q19) -> 0
A20: =+IF(BASE!B24="","",BASE!B24) -> 23XXR009 | B20: : | R20: =SUM(C20:Q20) -> 0 | S20: =BASE!A24 -> 9 | T20: =SUMIF($C$11:$Q$11,1,C20:Q20) -> 0 | U20: =SUMIF($C$11:$Q$11,2,C20:Q20) -> 0 | V20: =SUMIF($C$11:$Q$11,3,C20:Q20) -> 0 | W20: =SUMIF($C$11:$Q$11,4,C20:Q20) -> 0 | X20: =SUMIF($C$11:$Q$11,5,C20:Q20) -> 0
A21: =+IF(BASE!B25="","",BASE!B25) -> 23XXR010 | B21: : | R21: =SUM(C21:Q21) -> 0 | S21: =BASE!A25 -> 10 | T21: =SUMIF($C$11:$Q$11,1,C21:Q21) -> 0 | U21: =SUMIF($C$11:$Q$11,2,C21:Q21) -> 0 | V21: =SUMIF($C$11:$Q$11,3,C21:Q21) -> 0 | W21: =SUMIF($C$11:$Q$11,4,C21:Q21) -> 0 | X21: =SUMIF($C$11:$Q$11,5,C21:Q21) -> 0
A22: =+IF(BASE!B26="","",BASE!B26) -> 23XXR011 | B22: : | R22: =SUM(C22:Q22) -> 0 | S22: =BASE!A26 -> 11 | T22: =SUMIF($C$11:$Q$11,1,C22:Q22) -> 0 | U22: =SUMIF($C$11:$Q$11,2,C22:Q22) -> 0 | V22: =SUMIF($C$11:$Q$11,3,C22:Q22) -> 0 | W22: =SUMIF($C$11:$Q$11,4,C22:Q22) -> 0 | X22: =SUMIF($C$11:$Q$11,5,C22:Q22) -> 0
A23: =+IF(BASE!B27="","",BASE!B27) -> 23XXR012 | B23: : | R23: =SUM(C23:Q23) -> 0 | S23: =BASE!A27 -> 12 | T23: =SUMIF($C$11:$Q$11,1,C23:Q23) -> 0 | U23: =SUMIF($C$11:$Q$11,2,C23:Q23) -> 0 | V23: =SUMIF($C$11:$Q$11,3,C23:Q23) -> 0 | W23: =SUMIF($C$11:$Q$11,4,C23:Q23) -> 0 | X23: =SUMIF($C$11:$Q$11,5,C23:Q23) -> 0
... A461: =+IF(BASE!B465="","",BASE!B465) | B461: : | R461: =SUM(C461:Q461) -> 0 | S461: =BASE!A465 -> 450 | T461: =SUMIF($C$11:$Q$11,1,C461:Q461) -> 0 | U461: =SUMIF($C$11:$Q$11,2,C461:Q461) -> 0 | V461: =SUMIF($C$11:$Q$11,3,C461:Q461) -> 0 | W461: =SUMIF($C$11:$Q$11,4,C461:Q461) -> 0 | X461: =SUMIF($C$11:$Q$11,5,C461:Q461) -> 0
A462: =+IF(BASE!B466="","",BASE!B466)
A463: =+IF(BASE!B467="","",BASE!B467)

Sheet Tut-Ass-OA
A1: =BASE!A7 -> 0 | S1: =BASE!A7 -> 0
A2: =+BASE!A8 -> DEPARTMENT OF __________________________________ | S2: =BASE!A8 -> DEPARTMENT OF __________________________________
A3: =+BASE!A9 -> THEORY CUM PRACTICAL COURSE OUTCOME ANALYSIS | S3: =BASE!A9 -> THEORY CUM PRACTICAL COURSE OUTCOME ANALYSIS
A4: =BASE!A11 -> Name of Faculty(s) | B4: : | C4: =BASE!D11 -> 1 | G4: =BASE!G11 -> 1 | K4: =BASE!J11 -> 1 | O4: =BASE!M11 -> 1 | S4: Course Code | U4: =BASE!D12 -> 22ABXCXX
B5: : | C5: =BASE!D12 -> 22ABXCXX | G5: =BASE!G12 -> XXXXXXXX XXXXX XXXXXXXX | S5: Course Name | U5: =BASE!G12 -> XXXXXXXX XXXXX XXXXXXXX
A6: =BASE!A13 -> Branch / Year / Semester | B6: : | C6: =+BASE!D13 -> abcd | G6: =BASE!H13 -> 1 | J6: =BASE!L13 -> IV | L6: No. of Tutorials | S6: =BASE!A13 -> Branch / Year / Semester | U6: =BASE!D13 -> abcd | W6: =BASE!H13 -> 1 | X6: =BASE!L13 -> IV
A7: Asssesment | B7: : | C7: Tutorials / Assignments | I7: Credit Distribution | N7: =BASE!Q12 -> 3T+1P | S7: =A7 -> Asssesment | U7: =CONCATENATE(C7,I7) -> Tutorials / AssignmentsCredit Distribution
A9: Roll No | B9: Q. Nos | C9: 1 | D9: 2 | E9: 3 | F9: 4 | G9: 5 | R9: TOT MARKS | S9: S.NO | T9: CO1 | U9: CO2 | V9: CO3 | W9: CO4 | X9: CO5 | Y9: Tutorial
B10: Max Marks | C10: =IF($N$7="2T+1P", 2, IF($N$7="3T+1P", 2, IF($N$7="3.5T+0.5P", 3, " "))) -> 2 | D10: =IF($N$7="2T+1P", 2, IF($N$7="3T+1P", 2, IF($N$7="3.5T+0.5P", 3, " "))) -> 2 | E10: =IF($N$7="2T+1P", 2, IF($N$7="3T+1P", 2, IF($N$7="3.5T+0.5P", 3, " "))) -> 2 | F10: =IF($N$7="2T+1P", 2, IF($N$7="3T+1P", 2, IF($N$7="3.5T+0.5P", 3, " "))) -> 2 | G10: =IF($N$7="2T+1P", 2, IF($N$7="3T+1P", 2, IF($N$7="3.5T+0.5P", 3, " "))) -> 2 | T10: =SUMIF($C$11:$Q$11,1,C10:Q10) -> 2 | U10: =SUMIF($C$11:$Q$11,2,C10:Q10) -> 2 | V10: =SUMIF($C$11:$Q$11,3,C10:Q10) -> 2 | W10: =SUMIF($C$11:$Q$11,4,C10:Q10) -> 2 | X10: =SUMIF($C$11:$Q$11,5,C10:Q10) -> 2 | Y10: =IF($N$7="2T+1P","Out of 10 Marks", IF($N$7="3T+1P", "Out of 10 Marks", IF($N$7="3.5T+0.5P", "Out of 15 Marks", " "))) -> Out of 10 Marks
B11: COs | C11: 1 | D11: 2 | E11: 3 | F11: 4 | G11: 5
A12: =+BASE!B16 -> 23XXR001 | B12: : | C12: =IF($N$7="2T+1P", Y12/5, IF($N$7="3T+1P",Y12/5, IF($N$7="3.5T+0.5P",Y12/5, " "))) -> 0 | D12: =IF($N$7="2T+1P", Y12/5, IF($N$7="3T+1P",Y12/5, IF($N$7="3.5T+0.5P",Y12/5, " "))) -> 0 | E12: =IF($N$7="2T+1P", Y12/5, IF($N$7="3T+1P",Y12/5, IF($N$7="3.5T+0.5P",Y12/5, " "))) -> 0 | F12: =IF($N$7="2T+1P", Y12/5, IF($N$7="3T+1P",Y12/5, IF($N$7="3.5T+0.5P",Y12/5, " "))) -> 0 | G12: =IF($N$7="2T+1P", Y12/5, IF($N$7="3T+1P",Y12/5, IF($N$7="3.5T+0.5P",Y12/5, " "))) -> 0 | R12: =SUM(C12:Q12) -> 0 | S12: =BASE!A16 -> 1 | T12: =SUMIF($C$11:$Q$11,1,C12:Q12) -> 0 | U12: =SUMIF($C$11:$Q$11,2,C12:Q12) -> 0 | V12: =SUMIF($C$11:$Q$11,3,C12:Q12) -> 0 | W12: =SUMIF($C$11:$Q$11,4,C12:Q12) -> 0 | X12: =SUMIF($C$11:$Q$11,5,C12:Q12) -> 0
A13: =+BASE!B17 -> 23XXR002 | B13: : | C13: =IF($N$7="2T+1P", Y13/5, IF($N$7="3T+1P",Y13/5, IF($N$7="3.5T+0.5P",Y13/5, " "))) -> 0 | D13: =IF($N$7="2T+1P", Y13/5, IF($N$7="3T+1P",Y13/5, IF($N$7="3.5T+0.5P",Y13/5, " "))) -> 0 | E13: =IF($N$7="2T+1P", Y13/5, IF($N$7="3T+1P",Y13/5, IF($N$7="3.5T+0.5P",Y13/5, " "))) -> 0 | F13: =IF($N$7="2T+1P", Y13/5, IF($N$7="3T+1P",Y13/5, IF($N$7="3.5T+0.5P",Y13/5, " "))) -> 0 | G13: =IF($N$7="2T+1P", Y13/5, IF($N$7="3T+1P",Y13/5, IF($N$7="3.5T+0.5P",Y13/5, " "))) -> 0 | R13: =SUM(C13:Q13) -> 0 | S13: =BASE!A17 -> 2 | T13: =SUMIF($C$11:$Q$11,1,C13:Q13) -> 0 | U13: =SUMIF($C$11:$Q$11,2,C13:Q13) -> 0 | V13: =SUMIF($C$11:$Q$11,3,C13:Q13) -> 0 | W13: =SUMIF($C$11:$Q$11,4,C13:Q13) -> 0 | X13: =SUMIF($C$11:$Q$11,5,C13:Q13) -> 0
A14: =+BASE!B18 -> 23XXR003 | B14: : | C14: =IF($N$7="2T+1P", Y14/5, IF($N$7="3T+1P",Y14/5, IF($N$7="3.5T+0.5P",Y14/5, " "))) -> 0 | D14: =IF($N$7="2T+1P", Y14/5, IF($N$7="3T+1P",Y14/5, IF($N$7="3.5T+0.5P",Y14/5, " "))) -> 0 | E14: =IF($N$7="2T+1P", Y14/5, IF($N$7="3T+1P",Y14/5, IF($N$7="3.5T+0.5P",Y14/5, " "))) -> 0 | F14: =IF($N$7="2T+1P", Y14/5, IF($N$7="3T+1P",Y14/5, IF($N$7="3.5T+0.5P",Y14/5, " "))) -> 0 | G14: =IF($N$7="2T+1P", Y14/5, IF($N$7="3T+1P",Y14/5, IF($N$7="3.5T+0.5P",Y14/5, " "))) -> 0 | R14: =SUM(C14:Q14) -> 0 | S14: =BASE!A18 -> 3 | T14: =SUMIF($C$11:$Q$11,1,C14:Q14) -> 0 | U14: =SUMIF($C$11:$Q$11,2,C14:Q14) -> 0 | V14: =SUMIF($C$11:$Q$11,3,C14:Q14) -> 0 | W14: =SUMIF($C$11:$Q$11,4,C14:Q14) -> 0 | X14: =SUMIF($C$11:$Q$11,5,C14:Q14) -> 0
A15: =+BASE!B19 -> 23XXR004 | B15: : | C15: =IF($N$7="2T+1P", Y15/5, IF($N$7="3T+1P",Y15/5, IF($N$7="3.5T+0.5P",Y15/5, " "))) -> 0 | D15: =IF($N$7="2T+1P", Y15/5, IF($N$7="3T+1P",Y15/5, IF($N$7="3.5T+0.5P",Y15/5, " "))) -> 0 | E15: =IF($N$7="2T+1P", Y15/5, IF($N$7="3T+1P",Y15/5, IF($N$7="3.5T+0.5P",Y15/5, " "))) -> 0 | F15: =IF($N$7="2T+1P", Y15/5, IF($N$7="3T+1P",Y15/5, IF($N$7="3.5T+0.5P",Y15/5, " "))) -> 0 | G15: =IF($N$7="2T+1P", Y15/5, IF($N$7="3T+1P",Y15/5, IF($N$7="3.5T+0.5P",Y15/5, " "))) -> 0 | R15: =SUM(C15:Q15) -> 0 | S15: =BASE!A19 -> 4 | T15: =SUMIF($C$11:$Q$11,1,C15:Q15) -> 0 | U15: =SUMIF($C$11:$Q$11,2,C15:Q15) -> 0 | V15: =SUMIF($C$11:$Q$11,3,C15:Q15) -> 0 | W15: =SUMIF($C$11:$Q$11,4,C15:Q15) -> 0 | X15: =SUMIF($C$11:$Q$11,5,C15:Q15) -> 0
A16: =+BASE!B20 -> 23XXR005 | B16: : | C16: =IF($N$7="2T+1P", Y16/5, IF($N$7="3T+1P",Y16/5, IF($N$7="3.5T+0.5P",Y16/5, " "))) -> 0 | D16: =IF($N$7="2T+1P", Y16/5, IF($N$7="3T+1P",Y16/5, IF($N$7="3.5T+0.5P",Y16/5, " "))) -> 0 | E16: =IF($N$7="2T+1P", Y16/5, IF($N$7="3T+1P",Y16/5, IF($N$7="3.5T+0.5P",Y16/5, " "))) -> 0 | F16: =IF($N$7="2T+1P", Y16/5, IF($N$7="3T+1P",Y16/5, IF($N$7="3.5T+0.5P",Y16/5, " "))) -> 0 | G16: =IF($N$7="2T+1P", Y16/5, IF($N$7="3T+1P",Y16/5, IF($N$7="3.5T+0.5P",Y16/5, " "))) -> 0 | R16: =SUM(C16:Q16) -> 0 | S16: =BASE!A20 -> 5 | T16: =SUMIF($C$11:$Q$11,1,C16:Q16) -> 0 | U16: =SUMIF($C$11:$Q$11,2,C16:Q16) -> 0 | V16: =SUMIF($C$11:$Q$11,3,C16:Q16) -> 0 | W16: =SUMIF($C$11:$Q$11,4,C16:Q16) -> 0 | X16: =SUMIF($C$11:$Q$11,5,C16:Q16) -> 0
A17: =+BASE!B21 -> 23XXR006 | B17: : | C17: =IF($N$7="2T+1P", Y17/5, IF($N$7="3T+1P",Y17/5, IF($N$7="3.5T+0.5P",Y17/5, " "))) -> 0 | D17: =IF($N$7="2T+1P", Y17/5, IF($N$7="3T+1P",Y17/5, IF($N$7="3.5T+0.5P",Y17/5, " "))) -> 0 | E17: =IF($N$7="2T+1P", Y17/5, IF($N$7="3T+1P",Y17/5, IF($N$7="3.5T+0.5P",Y17/5, " "))) -> 0 | F17: =IF($N$7="2T+1P", Y17/5, IF($N$7="3T+1P",Y17/5, IF($N$7="3.5T+0.5P",Y17/5, " "))) -> 0 | G17: =IF($N$7="2T+1P", Y17/5, IF($N$7="3T+1P",Y17/5, IF($N$7="3.5T+0.5P",Y17/5, " "))) -> 0 | R17: =SUM(C17:Q17) -> 0 | S17: =BASE!A21 -> 6 | T17: =SUMIF($C$11:$Q$11,1,C17:Q17) -> 0 | U17: =SUMIF($C$11:$Q$11,2,C17:Q17) -> 0 | V17: =SUMIF($C$11:$Q$11,3,C17:Q17) -> 0 | W17: =SUMIF($C$11:$Q$11,4,C17:Q17) -> 0 | X17: =SUMIF($C$11:$Q$11,5,C17:Q17) -> 0
A18: =+BASE!B22 -> 23XXR007 | B18: : | C18: =IF($N$7="2T+1P", Y18/5, IF($N$7="3T+1P",Y18/5, IF($N$7="3.5T+0.5P",Y18/5, " "))) -> 0 | D18: =IF($N$7="2T+1P", Y18/5, IF($N$7="3T+1P",Y18/5, IF($N$7="3.5T+0.5P",Y18/5, " "))) -> 0 | E18: =IF($N$7="2T+1P", Y18/5, IF($N$7="3T+1P",Y18/5, IF($N$7="3.5T+0.5P",Y18/5, " "))) -> 0 | F18: =IF($N$7="2T+1P", Y18/5, IF($N$7="3T+1P",Y18/5, IF($N$7="3.5T+0.5P",Y18/5, " "))) -> 0 | G18: =IF($N$7="2T+1P", Y18/5, IF($N$7="3T+1P",Y18/5, IF($N$7="3.5T+0.5P",Y18/5, " "))) -> 0 | R18: =SUM(C18:Q18) -> 0 | S18: =BASE!A22 -> 7 | T18: =SUMIF($C$11:$Q$11,1,C18:Q18) -> 0 | U18: =SUMIF($C$11:$Q$11,2,C18:Q18) -> 0 | V18: =SUMIF($C$11:$Q$11,3,C18:Q18) -> 0 | W18: =SUMIF($C$11:$Q$11,4,C18:Q18) -> 0 | X18: =SUMIF($C$11:$Q$11,5,C18:Q18) -> 0
A19: =+BASE!B23 -> 23XXR008 | B19: : | C19: =IF($N$7="2T+1P", Y19/5, IF($N$7="3T+1P",Y19/5, IF($N$7="3.5T+0.5P",Y19/5, " "))) -> 0 | D19: =IF($N$7="2T+1P", Y19/5, IF($N$7="3T+1P",Y19/5, IF($N$7="3.5T+0.5P",Y19/5, " "))) -> 0 | E19: =IF($N$7="2T+1P", Y19/5, IF($N$7="3T+1P",Y19/5, IF($N$7="3.5T+0.5P",Y19/5, " "))) -> 0 | F19: =IF($N$7="2T+1P", Y19/5, IF($N$7="3T+1P",Y19/5, IF($N$7="3.5T+0.5P",Y19/5, " "))) -> 0 | G19: =IF($N$7="2T+1P", Y19/5, IF($N$7="3T+1P",Y19/5, IF($N$7="3.5T+0.5P",Y19/5, " "))) -> 0 | R19: =SUM(C19:Q19) -> 0 | S19: =BASE!A23 -> 8 | T19: =SUMIF($C$11:$Q$11,1,C19:Q19) -> 0 | U19: =SUMIF($C$11:$Q$11,2,C19:Q19) -> 0 | V19: =SUMIF($C$11:$Q$11,3,C19:Q19) -> 0 | W19: =SUMIF($C$11:$Q$11,4,C19:Q19) -> 0 | X19: =SUMIF($C$11:$Q$11,5,C19:Q19) -> 0
A20: =+BASE!B24 -> 23XXR009 | B20: : | C20: =IF($N$7="2T+1P", Y20/5, IF($N$7="3T+1P",Y20/5, IF($N$7="3.5T+0.5P",Y20/5, " "))) -> 0 | D20: =IF($N$7="2T+1P", Y20/5, IF($N$7="3T+1P",Y20/5, IF($N$7="3.5T+0.5P",Y20/5, " "))) -> 0 | E20: =IF($N$7="2T+1P", Y20/5, IF($N$7="3T+1P",Y20/5, IF($N$7="3.5T+0.5P",Y20/5, " "))) -> 0 | F20: =IF($N$7="2T+1P", Y20/5, IF($N$7="3T+1P",Y20/5, IF($N$7="3.5T+0.5P",Y20/5, " "))) -> 0 | G20: =IF($N$7="2T+1P", Y20/5, IF($N$7="3T+1P",Y20/5, IF($N$7="3.5T+0.5P",Y20/5, " "))) -> 0 | R20: =SUM(C20:Q20) -> 0 | S20: =BASE!A24 -> 9 | T20: =SUMIF($C$11:$Q$11,1,C20:Q20) -> 0 | U20: =SUMIF($C$11:$Q$11,2,C20:Q20) -> 0 | V20: =SUMIF($C$11:$Q$11,3,C20:Q20) -> 0 | W20: =SUMIF($C$11:$Q$11,4,C20:Q20) -> 0 | X20: =SUMIF($C$11:$Q$11,5,C20:Q20) -> 0
A21: =+BASE!B25 -> 23XXR010 | B21: : | C21: =IF($N$7="2T+1P", Y21/5, IF($N$7="3T+1P",Y21/5, IF($N$7="3.5T+0.5P",Y21/5, " "))) -> 0 | D21: =IF($N$7="2T+1P", Y21/5, IF($N$7="3T+1P",Y21/5, IF($N$7="3.5T+0.5P",Y21/5, " "))) -> 0 | E21: =IF($N$7="2T+1P", Y21/5, IF($N$7="3T+1P",Y21/5, IF($N$7="3.5T+0.5P",Y21/5, " "))) -> 0 | F21: =IF($N$7="2T+1P", Y21/5, IF($N$7="3T+1P",Y21/5, IF($N$7="3.5T+0.5P",Y21/5, " "))) -> 0 | G21: =IF($N$7="2T+1P", Y21/5, IF($N$7="3T+1P",Y21/5, IF($N$7="3.5T+0.5P",Y21/5, " "))) -> 0 | R21: =SUM(C21:Q21) -> 0 | S21: =BASE!A25 -> 10 | T21: =SUMIF($C$11:$Q$11,1,C21:Q21) -> 0 | U21: =SUMIF($C$11:$Q$11,2,C21:Q21) -> 0 | V21: =SUMIF($C$11:$Q$11,3,C21:Q21) -> 0 | W21: =SUMIF($C$11:$Q$11,4,C21:Q21) -> 0 | X21: =SUMIF($C$11:$Q$11,5,C21:Q21) -> 0
A22: =+BASE!B26 -> 23XXR011 | B22: : | C22: =IF($N$7="2T+1P", Y22/5, IF($N$7="3T+1P",Y22/5, IF($N$7="3.5T+0.5P",Y22/5, " "))) -> 0 | D22: =IF($N$7="2T+1P", Y22/5, IF($N$7="3T+1P",Y22/5, IF($N$7="3.5T+0.5P",Y22/5, " "))) -> 0 | E22: =IF($N$7="2T+1P", Y22/5, IF($N$7="3T+1P",Y22/5, IF($N$7="3.5T+0.5P",Y22/5, " "))) -> 0 | F22: =IF($N$7="2T+1P", Y22/5, IF($N$7="3T+1P",Y22/5, IF($N$7="3.5T+0.5P",Y22/5, " "))) -> 0 | G22: =IF($N$7="2T+1P", Y22/5, IF($N$7="3T+1P",Y22/5, IF($N$7="3.5T+0.5P",Y22/5, " "))) -> 0 | R22: =SUM(C22:Q22) -> 0 | S22: =BASE!A26 -> 11 | T22: =SUMIF($C$11:$Q$11,1,C22:Q22) -> 0 | U22: =SUMIF($C$11:$Q$11,2,C22:Q22) -> 0 | V22: =SUMIF($C$11:$Q$11,3,C22:Q22) -> 0 | W22: =SUMIF($C$11:$Q$11,4,C22:Q22) -> 0 | X22: =SUMIF($C$11:$Q$11,5,C22:Q22) -> 0
A23: =+BASE!B27 -> 23XXR012 | B23: : | C23: =IF($N$7="2T+1P", Y23/5, IF($N$7="3T+1P",Y23/5, IF($N$7="3.5T+0.5P",Y23/5, " "))) -> 0 | D23: =IF($N$7="2T+1P", Y23/5, IF($N$7="3T+1P",Y23/5, IF($N$7="3.5T+0.5P",Y23/5, " "))) -> 0 | E23: =IF($N$7="2T+1P", Y23/5, IF($N$7="3T+1P",Y23/5, IF($N$7="3.5T+0.5P",Y23/5, " "))) -> 0 | F23: =IF($N$7="2T+1P", Y23/5, IF($N$7="3T+1P",Y23/5, IF($N$7="3.5T+0.5P",Y23/5, " "))) -> 0 | G23: =IF($N$7="2T+1P", Y23/5, IF($N$7="3T+1P",Y23/5, IF($N$7="3.5T+0.5P",Y23/5, " "))) -> 0 | R23: =SUM(C23:Q23) -> 0 | S23: =BASE!A27 -> 12 | T23: =SUMIF($C$11:$Q$11,1,C23:Q23) -> 0 | U23: =SUMIF($C$11:$Q$11,2,C23:Q23) -> 0 | V23: =SUMIF($C$11:$Q$11,3,C23:Q23) -> 0 | W23: =SUMIF($C$11:$Q$11,4,C23:Q23) -> 0 | X23: =SUMIF($C$11:$Q$11,5,C23:Q23) -> 0
... A461: =+BASE!B465 -> 0 | B461: : | C461: =IF($N$7="2T+1P", Y461/5, IF($N$7="3T+1P",Y461/5, IF($N$7="3.5T+0.5P",Y461/5, " "))) -> 0 | D461: =IF($N$7="2T+1P", Y461/5, IF($N$7="3T+1P",Y461/5, IF($N$7="3.5T+0.5P",Y461/5, " "))) -> 0 | E461: =IF($N$7="2T+1P", Y461/5, IF($N$7="3T+1P",Y461/5, IF($N$7="3.5T+0.5P",Y461/5, " "))) -> 0 | F461: =IF($N$7="2T+1P", Y461/5, IF($N$7="3T+1P",Y461/5, IF($N$7="3.5T+0.5P",Y461/5, " "))) -> 0 | G461: =IF($N$7="2T+1P", Y461/5, IF($N$7="3T+1P",Y461/5, IF($N$7="3.5T+0.5P",Y461/5, " "))) -> 0 | R461: =SUM(C461:Q461) -> 0 | S461: =BASE!A465 -> 450 | T461: =SUMIF($C$11:$Q$11,1,C461:Q461) -> 0 | U461: =SUMIF($C$11:$Q$11,2,C461:Q461) -> 0 | V461: =SUMIF($C$11:$Q$11,3,C461:Q461) -> 0 | W461: =SUMIF($C$11:$Q$11,4,C461:Q461) -> 0 | X461: =SUMIF($C$11:$Q$11,5,C461:Q461) -> 0

Sheet LAB Asseement
A1: =BASE!A7 -> 0 | Q1: =BASE!A7 -> 0
A2: =+BASE!A8 -> DEPARTMENT OF __________________________________ | Q2: =BASE!A8 -> DEPARTMENT OF __________________________________
A3: =+BASE!A9 -> THEORY CUM PRACTICAL COURSE OUTCOME ANALYSIS | Q3: =BASE!A9 -> THEORY CUM PRACTICAL COURSE OUTCOME ANALYSIS
A4: =BASE!A11 -> Name of Faculty(s) | B4: : | C4: =BASE!D11 -> 1 | G4: =BASE!G11 -> 1 | L4: =BASE!J11 -> 1 | O4: =BASE!M11 -> 1 | Q4: Course Code | S4: =BASE!D12 -> 22ABXCXX
A5: =BASE!A12 -> Course Code and Name | B5: : | C5: =BASE!D12 -> 22ABXCXX | G5: =BASE!G12 -> XXXXXXXX XXXXX XXXXXXXX | Q5: Course Name | S5: =BASE!G12 -> XXXXXXXX XXXXX XXXXXXXX
A6: =BASE!A13 -> Branch / Year / Semester | B6: : | C6: =+BASE!D13 -> abcd | G6: =BASE!H13 -> 1 | I6: =BASE!L13 -> IV | K6: Model Lab Date | Q6: =A6 -> Branch / Year / Semester | S6: =+BASE!D13 -> abcd | U6: =BASE!H13 -> 1 | V6: =BASE!I13 -> 0
A7: Assesment | B7: : | C7: Lab Assesment / Model | G7: No. of Experiements | K7: Credit Distribution | O7: =BASE!Q12 -> 3T+1P | Q7: =A7 -> Assesment | S7: =C7 -> Lab Assesment / Model
A9: Roll No | C9: Continuous Lab Assessment | I9: Model Assessment | P9: TOT MARKS | Q9: S.NO | R9: CO1 | S9: CO2 | T9: CO3 | U9: CO4 | V9: CO5 | W9: Continuous Lab Assessment | X9: Model Assessment
B10: Max Marks | C10: =IF($O$7="2T+1P", 3, IF($O$7="3T+1P", 3, IF($O$7="3.5T+0.5P", 2, " "))) -> 3 | D10: =IF($O$7="2T+1P", 3, IF($O$7="3T+1P", 3, IF($O$7="3.5T+0.5P", 2, " "))) -> 3 | E10: =IF($O$7="2T+1P", 3, IF($O$7="3T+1P", 3, IF($O$7="3.5T+0.5P", 2, " "))) -> 3 | F10: =IF($O$7="2T+1P", 3, IF($O$7="3T+1P", 3, IF($O$7="3.5T+0.5P", 2, " "))) -> 3 | G10: =IF($O$7="2T+1P", 3, IF($O$7="3T+1P", 3, IF($O$7="3.5T+0.5P", 2, " "))) -> 3 | I10: =IF($O$7="2T+1P", 2, IF($O$7="3T+1P", 2, IF($O$7="3.5T+0.5P", " ", " "))) -> 2 | J10: =IF($O$7="2T+1P", 2, IF($O$7="3T+1P", 2, IF($O$7="3.5T+0.5P", " ", " "))) -> 2 | K10: =IF($O$7="2T+1P", 2, IF($O$7="3T+1P", 2, IF($O$7="3.5T+0.5P", " ", " "))) -> 2 | L10: =IF($O$7="2T+1P", 2, IF($O$7="3T+1P", 2, IF($O$7="3.5T+0.5P", " ", " "))) -> 2 | M10: =IF($O$7="2T+1P", 2, IF($O$7="3T+1P", 2, IF($O$7="3.5T+0.5P", " ", " "))) -> 2 | R10: =SUMIF($C$11:$O$11,1,C10:O10) -> 5 | S10: =SUMIF($C$11:$O$11,2,C10:O10) -> 5 | T10: =SUMIF($C$11:$O$11,3,C10:O10) -> 5 | U10: =SUMIF($C$11:$O$11,4,C10:O10) -> 5 | V10: =SUMIF($C$11:$O$11,5,C10:O10) -> 5 | W10: =IF($O$7="2T+1P","Out of 15 Marks", IF($O$7="3T+1P", "Out of 15 Marks", IF($O$7="3.5T+0.5P", "Out of 10 Marks", " "))) -> Out of 15 Marks | X10: =IF($O$7="2T+1P","Out of 10 Marks", IF($O$7="3T+1P", "Out of 10 Marks", IF($O$7="3.5T+0.5P", "- ", " "))) -> Out of 10 Marks
B11: COs | C11: 1 | D11: 2 | E11: 3 | F11: 4 | G11: 5 | I11: 1 | J11: 2 | K11: 3 | L11: 4 | M11: 5
A12: =+BASE!B16 -> 23XXR001 | B12: : | C12: =IF($O$7="2T+1P", W12/5, IF($O$7="3T+1P",W12/5, IF($O$7="3.5T+0.5P",W12/5, " "))) -> 0 | D12: =IF($O$7="2T+1P", W12/5, IF($O$7="3T+1P",W12/5, IF($O$7="3.5T+0.5P",W12/5, " "))) -> 0 | E12: =IF($O$7="2T+1P", W12/5, IF($O$7="3T+1P",W12/5, IF($O$7="3.5T+0.5P",W12/5, " "))) -> 0 | F12: =IF($O$7="2T+1P", W12/5, IF($O$7="3T+1P",W12/5, IF($O$7="3.5T+0.5P",W12/5, " "))) -> 0 | G12: =IF($O$7="2T+1P", W12/5, IF($O$7="3T+1P",W12/5, IF($O$7="3.5T+0.5P",W12/5, " "))) -> 0 | I12: =IF($O$7="2T+1P", X12/5, IF($O$7="3T+1P",X12/5, IF($O$7="3.5T+0.5P",X12/5, " "))) -> 0 | J12: =IF($O$7="2T+1P", X12/5, IF($O$7="3T+1P",X12/5, IF($O$7="3.5T+0.5P",X12/5, " "))) -> 0 | K12: =IF($O$7="2T+1P", X12/5, IF($O$7="3T+1P",X12/5, IF($O$7="3.5T+0.5P",X12/5, " "))) -> 0 | L12: =IF($O$7="2T+1P", X12/5, IF($O$7="3T+1P",X12/5, IF($O$7="3.5T+0.5P",X12/5, " "))) -> 0 | M12: =IF($O$7="2T+1P", X12/5, IF($O$7="3T+1P",X12/5, IF($O$7="3.5T+0.5P",X12/5, " "))) -> 0 | P12: =SUM(C12:O12) -> 0 | Q12: =BASE!A16 -> 1 | R12: =SUMIF($C$11:$O$11,1,C12:O12) -> 0 | S12: =SUMIF($C$11:$O$11,2,D12:P12) -> 0 | T12: =SUMIF($C$11:$O$11,3,E12:Q12) -> 0 | U12: =SUMIF($C$11:$O$11,4,C12:O12) -> 0 | V12: =SUMIF($C$11:$O$11,5,C12:O12) -> 0
A13: =+BASE!B17 -> 23XXR002 | B13: : | C13: =IF($O$7="2T+1P", W13/5, IF($O$7="3T+1P",W13/5, IF($O$7="3.5T+0.5P",W13/5, " "))) -> 0 | D13: =IF($O$7="2T+1P", W13/5, IF($O$7="3T+1P",W13/5, IF($O$7="3.5T+0.5P",W13/5, " "))) -> 0 | E13: =IF($O$7="2T+1P", W13/5, IF($O$7="3T+1P",W13/5, IF($O$7="3.5T+0.5P",W13/5, " "))) -> 0 | F13: =IF($O$7="2T+1P", W13/5, IF($O$7="3T+1P",W13/5, IF($O$7="3.5T+0.5P",W13/5, " "))) -> 0 | G13: =IF($O$7="2T+1P", W13/5, IF($O$7="3T+1P",W13/5, IF($O$7="3.5T+0.5P",W13/5, " "))) -> 0 | I13: =IF($O$7="2T+1P", X13/5, IF($O$7="3T+1P",X13/5, IF($O$7="3.5T+0.5P",X13/5, " "))) -> 0 | J13: =IF($O$7="2T+1P", X13/5, IF($O$7="3T+1P",X13/5, IF($O$7="3.5T+0.5P",X13/5, " "))) -> 0 | K13: =IF($O$7="2T+1P", X13/5, IF($O$7="3T+1P",X13/5, IF($O$7="3.5T+0.5P",X13/5, " "))) -> 0 | L13: =IF($O$7="2T+1P", X13/5, IF($O$7="3T+1P",X13/5, IF($O$7="3.5T+0.5P",X13/5, " "))) -> 0 | M13: =IF($O$7="2T+1P", X13/5, IF($O$7="3T+1P",X13/5, IF($O$7="3.5T+0.5P",X13/5, " "))) -> 0 | P13: =SUM(C13:O13) -> 0 | Q13: =BASE!A17 -> 2 | R13: =SUMIF($C$11:$O$11,1,C13:O13) -> 0 | S13: =SUMIF($C$11:$O$11,2,D13:P13) -> 0 | T13: =SUMIF($C$11:$O$11,3,E13:Q13) -> 0 | U13: =SUMIF($C$11:$O$11,4,C13:O13) -> 0 | V13: =SUMIF($C$11:$O$11,5,C13:O13) -> 0
A14: =+BASE!B18 -> 23XXR003 | B14: : | C14: =IF($O$7="2T+1P", W14/5, IF($O$7="3T+1P",W14/5, IF($O$7="3.5T+0.5P",W14/5, " "))) -> 0 | D14: =IF($O$7="2T+1P", W14/5, IF($O$7="3T+1P",W14/5, IF($O$7="3.5T+0.5P",W14/5, " "))) -> 0 | E14: =IF($O$7="2T+1P", W14/5, IF($O$7="3T+1P",W14/5, IF($O$7="3.5T+0.5P",W14/5, " "))) -> 0 | F14: =IF($O$7="2T+1P", W14/5, IF($O$7="3T+1P",W14/5, IF($O$7="3.5T+0.5P",W14/5, " "))) -> 0 | G14: =IF($O$7="2T+1P", W14/5, IF($O$7="3T+1P",W14/5, IF($O$7="3.5T+0.5P",W14/5, " "))) -> 0 | I14: =IF($O$7="2T+1P", X14/5, IF($O$7="3T+1P",X14/5, IF($O$7="3.5T+0.5P",X14/5, " "))) -> 0 | J14: =IF($O$7="2T+1P", X14/5, IF($O$7="3T+1P",X14/5, IF($O$7="3.5T+0.5P",X14/5, " "))) -> 0 | K14: =IF($O$7="2T+1P", X14/5, IF($O$7="3T+1P",X14/5, IF($O$7="3.5T+0.5P",X14/5, " "))) -> 0 | L14: =IF($O$7="2T+1P", X14/5, IF($O$7="3T+1P",X14/5, IF($O$7="3.5T+0.5P",X14/5, " "))) -> 0 | M14: =IF($O$7="2T+1P", X14/5, IF($O$7="3T+1P",X14/5, IF($O$7="3.5T+0.5P",X14/5, " "))) -> 0 | P14: =SUM(C14:O14) -> 0 | Q14: =BASE!A18 -> 3 | R14: =SUMIF($C$11:$O$11,1,C14:O14) -> 0 | S14: =SUMIF($C$11:$O$11,2,D14:P14) -> 0 | T14: =SUMIF($C$11:$O$11,3,E14:Q14) -> 0 | U14: =SUMIF($C$11:$O$11,4,C14:O14) -> 0 | V14: =SUMIF($C$11:$O$11,5,C14:O14) -> 0
A15: =+BASE!B19 -> 23XXR004 | B15: : | C15: =IF($O$7="2T+1P", W15/5, IF($O$7="3T+1P",W15/5, IF($O$7="3.5T+0.5P",W15/5, " "))) -> 0 | D15: =IF($O$7="2T+1P", W15/5, IF($O$7="3T+1P",W15/5, IF($O$7="3.5T+0.5P",W15/5, " "))) -> 0 | E15: =IF($O$7="2T+1P", W15/5, IF($O$7="3T+1P",W15/5, IF($O$7="3.5T+0.5P",W15/5, " "))) -> 0 | F15: =IF($O$7="2T+1P", W15/5, IF($O$7="3T+1P",W15/5, IF($O$7="3.5T+0.5P",W15/5, " "))) -> 0 | G15: =IF($O$7="2T+1P", W15/5, IF($O$7="3T+1P",W15/5, IF($O$7="3.5T+0.5P",W15/5, " "))) -> 0 | I15: =IF($O$7="2T+1P", X15/5, IF($O$7="3T+1P",X15/5, IF($O$7="3.5T+0.5P",X15/5, " "))) -> 0 | J15: =IF($O$7="2T+1P", X15/5, IF($O$7="3T+1P",X15/5, IF($O$7="3.5T+0.5P",X15/5, " "))) -> 0 | K15: =IF($O$7="2T+1P", X15/5, IF($O$7="3T+1P",X15/5, IF($O$7="3.5T+0.5P",X15/5, " "))) -> 0 | L15: =IF($O$7="2T+1P", X15/5, IF($O$7="3T+1P",X15/5, IF($O$7="3.5T+0.5P",X15/5, " "))) -> 0 | M15: =IF($O$7="2T+1P", X15/5, IF($O$7="3T+1P",X15/5, IF($O$7="3.5T+0.5P",X15/5, " "))) -> 0 | P15: =SUM(C15:O15) -> 0 | Q15: =BASE!A19 -> 4 | R15: =SUMIF($C$11:$O$11,1,C15:O15) -> 0 | S15: =SUMIF($C$11:$O$11,2,D15:P15) -> 0 | T15: =SUMIF($C$11:$O$11,3,E15:Q15) -> 0 | U15: =SUMIF($C$11:$O$11,4,C15:O15) -> 0 | V15: =SUMIF($C$11:$O$11,5,C15:O15) -> 0
A16: =+BASE!B20 -> 23XXR005 | B16: : | C16: =IF($O$7="2T+1P", W16/5, IF($O$7="3T+1P",W16/5, IF($O$7="3.5T+0.5P",W16/5, " "))) -> 0 | D16: =IF($O$7="2T+1P", W16/5, IF($O$7="3T+1P",W16/5, IF($O$7="3.5T+0.5P",W16/5, " "))) -> 0 | E16: =IF($O$7="2T+1P", W16/5, IF($O$7="3T+1P",W16/5, IF($O$7="3.5T+0.5P",W16/5, " "))) -> 0 | F16: =IF($O$7="2T+1P", W16/5, IF($O$7="3T+1P",W16/5, IF($O$7="3.5T+0.5P",W16/5, " "))) -> 0 | G16: =IF($O$7="2T+1P", W16/5, IF($O$7="3T+1P",W16/5, IF($O$7="3.5T+0.5P",W16/5, " "))) -> 0 | I16: =IF($O$7="2T+1P", X16/5, IF($O$7="3T+1P",X16/5, IF($O$7="3.5T+0.5P",X16/5, " "))) -> 0 | J16: =IF($O$7="2T+1P", X16/5, IF($O$7="3T+1P",X16/5, IF($O$7="3.5T+0.5P",X16/5, " "))) -> 0 | K16: =IF($O$7="2T+1P", X16/5, IF($O$7="3T+1P",X16/5, IF($O$7="3.5T+0.5P",X16/5, " "))) -> 0 | L16: =IF($O$7="2T+1P", X16/5, IF($O$7="3T+1P",X16/5, IF($O$7="3.5T+0.5P",X16/5, " "))) -> 0 | M16: =IF($O$7="2T+1P", X16/5, IF($O$7="3T+1P",X16/5, IF($O$7="3.5T+0.5P",X16/5, " "))) -> 0 | P16: =SUM(C16:O16) -> 0 | Q16: =BASE!A20 -> 5 | R16: =SUMIF($C$11:$O$11,1,C16:O16) -> 0 | S16: =SUMIF($C$11:$O$11,2,D16:P16) -> 0 | T16: =SUMIF($C$11:$O$11,3,E16:Q16) -> 0 | U16: =SUMIF($C$11:$O$11,4,C16:O16) -> 0 | V16: =SUMIF($C$11:$O$11,5,C16:O16) -> 0
A17: =+BASE!B21 -> 23XXR006 | B17: : | C17: =IF($O$7="2T+1P", W17/5, IF($O$7="3T+1P",W17/5, IF($O$7="3.5T+0.5P",W17/5, " "))) -> 0 | D17: =IF($O$7="2T+1P", W17/5, IF($O$7="3T+1P",W17/5, IF($O$7="3.5T+0.5P",W17/5, " "))) -> 0 | E17: =IF($O$7="2T+1P", W17/5, IF($O$7="3T+1P",W17/5, IF($O$7="3.5T+0.5P",W17/5, " "))) -> 0 | F17: =IF($O$7="2T+1P", W17/5, IF($O$7="3T+1P",W17/5, IF($O$7="3.5T+0.5P",W17/5, " "))) -> 0 | G17: =IF($O$7="2T+1P", W17/5, IF($O$7="3T+1P",W17/5, IF($O$7="3.5T+0.5P",W17/5, " "))) -> 0 | I17: =IF($O$7="2T+1P", X17/5, IF($O$7="3T+1P",X17/5, IF($O$7="3.5T+0.5P",X17/5, " "))) -> 0 | J17: =IF($O$7="2T+1P", X17/5, IF($O$7="3T+1P",X17/5, IF($O$7="3.5T+0.5P",X17/5, " "))) -> 0 | K17: =IF($O$7="2T+1P", X17/5, IF($O$7="3T+1P",X17/5, IF($O$7="3.5T+0.5P",X17/5, " "))) -> 0 | L17: =IF($O$7="2T+1P", X17/5, IF($O$7="3T+1P",X17/5, IF($O$7="3.5T+0.5P",X17/5, " "))) -> 0 | M17: =IF($O$7="2T+1P", X17/5, IF($O$7="3T+1P",X17/5, IF($O$7="3.5T+0.5P",X17/5, " "))) -> 0 | P17: =SUM(C17:O17) -> 0 | Q17: =BASE!A21 -> 6 | R17: =SUMIF($C$11:$O$11,1,C17:O17) -> 0 | S17: =SUMIF($C$11:$O$11,2,D17:P17) -> 0 | T17: =SUMIF($C$11:$O$11,3,E17:Q17) -> 0 | U17: =SUMIF($C$11:$O$11,4,C17:O17) -> 0 | V17: =SUMIF($C$11:$O$11,5,C17:O17) -> 0
A18: =+BASE!B22 -> 23XXR007 | B18: : | C18: =IF($O$7="2T+1P", W18/5, IF($O$7="3T+1P",W18/5, IF($O$7="3.5T+0.5P",W18/5, " "))) -> 0 | D18: =IF($O$7="2T+1P", W18/5, IF($O$7="3T+1P",W18/5, IF($O$7="3.5T+0.5P",W18/5, " "))) -> 0 | E18: =IF($O$7="2T+1P", W18/5, IF($O$7="3T+1P",W18/5, IF($O$7="3.5T+0.5P",W18/5, " "))) -> 0 | F18: =IF($O$7="2T+1P", W18/5, IF($O$7="3T+1P",W18/5, IF($O$7="3.5T+0.5P",W18/5, " "))) -> 0 | G18: =IF($O$7="2T+1P", W18/5, IF($O$7="3T+1P",W18/5, IF($O$7="3.5T+0.5P",W18/5, " "))) -> 0 | I18: =IF($O$7="2T+1P", X18/5, IF($O$7="3T+1P",X18/5, IF($O$7="3.5T+0.5P",X18/5, " "))) -> 0 | J18: =IF($O$7="2T+1P", X18/5, IF($O$7="3T+1P",X18/5, IF($O$7="3.5T+0.5P",X18/5, " "))) -> 0 | K18: =IF($O$7="2T+1P", X18/5, IF($O$7="3T+1P",X18/5, IF($O$7="3.5T+0.5P",X18/5, " "))) -> 0 | L18: =IF($O$7="2T+1P", X18/5, IF($O$7="3T+1P",X18/5, IF($O$7="3.5T+0.5P",X18/5, " "))) -> 0 | M18: =IF($O$7="2T+1P", X18/5, IF($O$7="3T+1P",X18/5, IF($O$7="3.5T+0.5P",X18/5, " "))) -> 0 | P18: =SUM(C18:O18) -> 0 | Q18: =BASE!A22 -> 7 | R18: =SUMIF($C$11:$O$11,1,C18:O18) -> 0 | S18: =SUMIF($C$11:$O$11,2,D18:P18) -> 0 | T18: =SUMIF($C$11:$O$11,3,E18:Q18) -> 0 | U18: =SUMIF($C$11:$O$11,4,C18:O18) -> 0 | V18: =SUMIF($C$11:$O$11,5,C18:O18) -> 0
A19: =+BASE!B23 -> 23XXR008 | B19: : | C19: =IF($O$7="2T+1P", W19/5, IF($O$7="3T+1P",W19/5, IF($O$7="3.5T+0.5P",W19/5, " "))) -> 0 | D19: =IF($O$7="2T+1P", W19/5, IF($O$7="3T+1P",W19/5, IF($O$7="3.5T+0.5P",W19/5, " "))) -> 0 | E19: =IF($O$7="2T+1P", W19/5, IF($O$7="3T+1P",W19/5, IF($O$7="3.5T+0.5P",W19/5, " "))) -> 0 | F19: =IF($O$7="2T+1P", W19/5, IF($O$7="3T+1P",W19/5, IF($O$7="3.5T+0.5P",W19/5, " "))) -> 0 | G19: =IF($O$7="2T+1P", W19/5, IF($O$7="3T+1P",W19/5, IF($O$7="3.5T+0.5P",W19/5, " "))) -> 0 | I19: =IF($O$7="2T+1P", X19/5, IF($O$7="3T+1P",X19/5, IF($O$7="3.5T+0.5P",X19/5, " "))) -> 0 | J19: =IF($O$7="2T+1P", X19/5, IF($O$7="3T+1P",X19/5, IF($O$7="3.5T+0.5P",X19/5, " "))) -> 0 | K19: =IF($O$7="2T+1P", X19/5, IF($O$7="3T+1P",X19/5, IF($O$7="3.5T+0.5P",X19/5, " "))) -> 0 | L19: =IF($O$7="2T+1P", X19/5, IF($O$7="3T+1P",X19/5, IF($O$7="3.5T+0.5P",X19/5, " "))) -> 0 | M19: =IF($O$7="2T+1P", X19/5, IF($O$7="3T+1P",X19/5, IF($O$7="3.5T+0.5P",X19/5, " "))) -> 0 | P19: =SUM(C19:O19) -> 0 | Q19: =BASE!A23 -> 8 | R19: =SUMIF($C$11:$O$11,1,C19:O19) -> 0 | S19: =SUMIF($C$11:$O$11,2,D19:P19) -> 0 | T19: =SUMIF($C$11:$O$11,3,E19:Q19) -> 0 | U19: =SUMIF($C$11:$O$11,4,C19:O19) -> 0 | V19: =SUMIF($C$11:$O$11,5,C19:O19) -> 0
A20: =+BASE!B24 -> 23XXR009 | B20: : | C20: =IF($O$7="2T+1P", W20/5, IF($O$7="3T+1P",W20/5, IF($O$7="3.5T+0.5P",W20/5, " "))) -> 0 | D20: =IF($O$7="2T+1P", W20/5, IF($O$7="3T+1P",W20/5, IF($O$7="3.5T+0.5P",W20/5, " "))) -> 0 | E20: =IF($O$7="2T+1P", W20/5, IF($O$7="3T+1P",W20/5, IF($O$7="3.5T+0.5P",W20/5, " "))) -> 0 | F20: =IF($O$7="2T+1P", W20/5, IF($O$7="3T+1P",W20/5, IF($O$7="3.5T+0.5P",W20/5, " "))) -> 0 | G20: =IF($O$7="2T+1P", W20/5, IF($O$7="3T+1P",W20/5, IF($O$7="3.5T+0.5P",W20/5, " "))) -> 0 | I20: =IF($O$7="2T+1P", X20/5, IF($O$7="3T+1P",X20/5, IF($O$7="3.5T+0.5P",X20/5, " "))) -> 0 | J20: =IF($O$7="2T+1P", X20/5, IF($O$7="3T+1P",X20/5, IF($O$7="3.5T+0.5P",X20/5, " "))) -> 0 | K20: =IF($O$7="2T+1P", X20/5, IF($O$7="3T+1P",X20/5, IF($O$7="3.5T+0.5P",X20/5, " "))) -> 0 | L20: =IF($O$7="2T+1P", X20/5, IF($O$7="3T+1P",X20/5, IF($O$7="3.5T+0.5P",X20/5, " "))) -> 0 | M20: =IF($O$7="2T+1P", X20/5, IF($O$7="3T+1P",X20/5, IF($O$7="3.5T+0.5P",X20/5, " "))) -> 0 | P20: =SUM(C20:O20) -> 0 | Q20: =BASE!A24 -> 9 | R20: =SUMIF($C$11:$O$11,1,C20:O20) -> 0 | S20: =SUMIF($C$11:$O$11,2,D20:P20) -> 0 | T20: =SUMIF($C$11:$O$11,3,E20:Q20) -> 0 | U20: =SUMIF($C$11:$O$11,4,C20:O20) -> 0 | V20: =SUMIF($C$11:$O$11,5,C20:O20) -> 0
A21: =+BASE!B25 -> 23XXR010 | B21: : | C21: =IF($O$7="2T+1P", W21/5, IF($O$7="3T+1P",W21/5, IF($O$7="3.5T+0.5P",W21/5, " "))) -> 0 | D21: =IF($O$7="2T+1P", W21/5, IF($O$7="3T+1P",W21/5, IF($O$7="3.5T+0.5P",W21/5, " "))) -> 0 | E21: =IF($O$7="2T+1P", W21/5, IF($O$7="3T+1P",W21/5, IF($O$7="3.5T+0.5P",W21/5, " "))) -> 0 | F21: =IF($O$7="2T+1P", W21/5, IF($O$7="3T+1P",W21/5, IF($O$7="3.5T+0.5P",W21/5, " "))) -> 0 | G21: =IF($O$7="2T+1P", W21/5, IF($O$7="3T+1P",W21/5, IF($O$7="3.5T+0.5P",W21/5, " "))) -> 0 | I21: =IF($O$7="2T+1P", X21/5, IF($O$7="3T+1P",X21/5, IF($O$7="3.5T+0.5P",X21/5, " "))) -> 0 | J21: =IF($O$7="2T+1P", X21/5, IF($O$7="3T+1P",X21/5, IF($O$7="3.5T+0.5P",X21/5, " "))) -> 0 | K21: =IF($O$7="2T+1P", X21/5, IF($O$7="3T+1P",X21/5, IF($O$7="3.5T+0.5P",X21/5, " "))) -> 0 | L21: =IF($O$7="2T+1P", X21/5, IF($O$7="3T+1P",X21/5, IF($O$7="3.5T+0.5P",X21/5, " "))) -> 0 | M21: =IF($O$7="2T+1P", X21/5, IF($O$7="3T+1P",X21/5, IF($O$7="3.5T+0.5P",X21/5, " "))) -> 0 | P21: =SUM(C21:O21) -> 0 | Q21: =BASE!A25 -> 10 | R21: =SUMIF($C$11:$O$11,1,C21:O21) -> 0 | S21: =SUMIF($C$11:$O$11,2,D21:P21) -> 0 | T21: =SUMIF($C$11:$O$11,3,E21:Q21) -> 0 | U21: =SUMIF($C$11:$O$11,4,C21:O21) -> 0 | V21: =SUMIF($C$11:$O$11,5,C21:O21) -> 0
A22: =+BASE!B26 -> 23XXR011 | B22: : | C22: =IF($O$7="2T+1P", W22/5, IF($O$7="3T+1P",W22/5, IF($O$7="3.5T+0.5P",W22/5, " "))) -> 0 | D22: =IF($O$7="2T+1P", W22/5, IF($O$7="3T+1P",W22/5, IF($O$7="3.5T+0.5P",W22/5, " "))) -> 0 | E22: =IF($O$7="2T+1P", W22/5, IF($O$7="3T+1P",W22/5, IF($O$7="3.5T+0.5P",W22/5, " "))) -> 0 | F22: =IF($O$7="2T+1P", W22/5, IF($O$7="3T+1P",W22/5, IF($O$7="3.5T+0.5P",W22/5, " "))) -> 0 | G22: =IF($O$7="2T+1P", W22/5, IF($O$7="3T+1P",W22/5, IF($O$7="3.5T+0.5P",W22/5, " "))) -> 0 | I22: =IF($O$7="2T+1P", X22/5, IF($O$7="3T+1P",X22/5, IF($O$7="3.5T+0.5P",X22/5, " "))) -> 0 | J22: =IF($O$7="2T+1P", X22/5, IF($O$7="3T+1P",X22/5, IF($O$7="3.5T+0.5P",X22/5, " "))) -> 0 | K22: =IF($O$7="2T+1P", X22/5, IF($O$7="3T+1P",X22/5, IF($O$7="3.5T+0.5P",X22/5, " "))) -> 0 | L22: =IF($O$7="2T+1P", X22/5, IF($O$7="3T+1P",X22/5, IF($O$7="3.5T+0.5P",X22/5, " "))) -> 0 | M22: =IF($O$7="2T+1P", X22/5, IF($O$7="3T+1P",X22/5, IF($O$7="3.5T+0.5P",X22/5, " "))) -> 0 | P22: =SUM(C22:O22) -> 0 | Q22: =BASE!A26 -> 11 | R22: =SUMIF($C$11:$O$11,1,C22:O22) -> 0 | S22: =SUMIF($C$11:$O$11,2,D22:P22) -> 0 | T22: =SUMIF($C$11:$O$11,3,E22:Q22) -> 0 | U22: =SUMIF($C$11:$O$11,4,C22:O22) -> 0 | V22: =SUMIF($C$11:$O$11,5,C22:O22) -> 0
A23: =+BASE!B27 -> 23XXR012 | B23: : | C23: =IF($O$7="2T+1P", W23/5, IF($O$7="3T+1P",W23/5, IF($O$7="3.5T+0.5P",W23/5, " "))) -> 0 | D23: =IF($O$7="2T+1P", W23/5, IF($O$7="3T+1P",W23/5, IF($O$7="3.5T+0.5P",W23/5, " "))) -> 0 | E23: =IF($O$7="2T+1P", W23/5, IF($O$7="3T+1P",W23/5, IF($O$7="3.5T+0.5P",W23/5, " "))) -> 0 | F23: =IF($O$7="2T+1P", W23/5, IF($O$7="3T+1P",W23/5, IF($O$7="3.5T+0.5P",W23/5, " "))) -> 0 | G23: =IF($O$7="2T+1P", W23/5, IF($O$7="3T+1P",W23/5, IF($O$7="3.5T+0.5P",W23/5, " "))) -> 0 | I23: =IF($O$7="2T+1P", X23/5, IF($O$7="3T+1P",X23/5, IF($O$7="3.5T+0.5P",X23/5, " "))) -> 0 | J23: =IF($O$7="2T+1P", X23/5, IF($O$7="3T+1P",X23/5, IF($O$7="3.5T+0.5P",X23/5, " "))) -> 0 | K23: =IF($O$7="2T+1P", X23/5, IF($O$7="3T+1P",X23/5, IF($O$7="3.5T+0.5P",X23/5, " "))) -> 0 | L23: =IF($O$7="2T+1P", X23/5, IF($O$7="3T+1P",X23/5, IF($O$7="3.5T+0.5P",X23/5, " "))) -> 0 | M23: =IF($O$7="2T+1P", X23/5, IF($O$7="3T+1P",X23/5, IF($O$7="3.5T+0.5P",X23/5, " "))) -> 0 | P23: =SUM(C23:O23) -> 0 | Q23: =BASE!A27 -> 12 | R23: =SUMIF($C$11:$O$11,1,C23:O23) -> 0 | S23: =SUMIF($C$11:$O$11,2,D23:P23) -> 0 | T23: =SUMIF($C$11:$O$11,3,E23:Q23) -> 0 | U23: =SUMIF($C$11:$O$11,4,C23:O23) -> 0 | V23: =SUMIF($C$11:$O$11,5,C23:O23) -> 0
