Workbook
Name _GoBack: 'Course Ass Report'!$E$9

Sheet Target
A1: KONGU ENGINEERING COLLEGE, ERODE - 638 060
A2: DEPARTMENT OF ________________________________________
A3: THEORY CUM LABORATORY COURSE OUTCOME ANALYSIS - TARGET FIXING
A4: S.NO | B4: (X-2) SEM | H4: (X-1) SEM
B5: A Sec | C5: B sec | D5: C Sec | E5: D Sec | F5: E Sec | G5: F Sec | H5: A Sec | I5: B sec | J5: C Sec | K5: D Sec | L5: E Sec | M5: F Sec
A6: 1
A7: 2
A8: 3
A9: 4
A10: 5
A11: 6
A12: 7
A13: 8
A14: 9
A15: 10
A16: 11
A17: 12
... A75: 70
A77: Mean of individual class GPA(a.) | B77: =IFERROR(AVERAGE(B6:B76),0) -> 0 | C77: =IFERROR(AVERAGE(C6:C76),0) -> 0 | D77: =IFERROR(AVERAGE(D6:D76),0) -> 0 | E77: =IFERROR(AVERAGE(E6:E76),0) -> 0 | F77: =IFERROR(AVERAGE(F6:F76),0) -> 0 | G77: =IFERROR(AVERAGE(G6:G76),0) -> 0 | H77: =IFERROR(AVERAGE(H6:H76),0) -> 0 | I77: =IFERROR(AVERAGE(I6:I76),0) -> 0 | ... M77: =IFERROR(AVERAGE(M6:M76),0) -> 0
A78: Total No. of successful students (b.) | B78: =COUNTA(B6:B76) -> 0 | C78: =COUNTA(C6:C76) -> 0 | D78: =COUNTA(D6:D76) -> 0 | E78: =COUNTA(E6:E76) -> 0 | F78: =COUNTA(F6:F76) -> 0 | G78: =COUNTA(G6:G76) -> 0 | H78: =COUNTA(H6:H76) -> 0 | I78: =COUNTA(I6:I76) -> 0 | ... M78: =COUNTA(M6:M76) -> 0
A79: Total No. of students appeared in the examination (c.)
A80: Academic Performance Index (d.) | B80: =IFERROR(B77*(B78/B79),0) -> 0 | C80: =IFERROR(C77*(C78/C79),0) -> 0 | D80: =IFERROR(D77*(D78/D79),0) -> 0 | E80: =IFERROR(E77*(E78/E79),0) -> 0 | F80: =IFERROR(F77*(F78/F79),0) -> 0 | G80: =IFERROR(G77*(G78/G79),0) -> 0 | H80: =IFERROR(H77*(H78/H79),0) -> 0 | I80: =IFERROR(I77*(I78/I79),0) -> 0 | ... M80: =IFERROR(M77*(M78/M79),0) -> 0
A81: Total No. of students above API (e.) | B81: =COUNTIF(B6:B76,">="&B80) -> 0 | C81: =COUNTIF(C6:C76,">="&C80) -> 0 | D81: =COUNTIF(D6:D76,">="&D80) -> 0 | E81: =COUNTIF(E6:E76,">="&E80) -> 0 | F81: =COUNTIF(F6:F76,">="&F80) -> 0 | G81: =COUNTIF(G6:G76,">="&G80) -> 0 | H81: =COUNTIF(H6:H76,">="&H80) -> 0 | I81: =COUNTIF(I6:I76,">="&I80) -> 0 | ... M81: =COUNTIF(M6:M76,">="&M80) -> 0
A82: Percentage of Equal and above API for individual class (f.) | B82: =IFERROR((B81/B79)*100,0) -> 0 | C82: =IFERROR((C81/C79)*100,0) -> 0 | D82: =IFERROR((D81/D79)*100,0) -> 0 | E82: =IFERROR((E81/E79)*100,0) -> 0 | F82: =IFERROR((F81/F79)*100,0) -> 0 | G82: =IFERROR((G81/G79)*100,0) -> 0 | H82: =IFERROR((H81/H79)*100,0) -> 0 | I82: =IFERROR((I81/I79)*100,0) -> 0 | ... M82: =IFERROR((M81/M79)*100,0) -> 0
A83: Toatl Average of ALL sections | B83: =IFERROR(SUM(B82:G82)/COUNTIF(B82:G82,"<>0"),0) -> 0 | H83: =IFERROR(SUM(H82:M82)/COUNTIF(H82:M82,"<>0"),0) -> 0
A84: Semester (X-2) | B84: =B83 -> 0
A85: Semester (X-1) | B85: =H83 -> 0
A86: Avg of previous two semester | B86: =AVERAGE(B84:B85) -> 0

Sheet BASE
A1: KONGU ENGINEERING COLLEGE, ERODE - 638 060
A2: DEPARTMENT OF ______________________________
A3: PROJECT WORK COURSE OUTCOME ANALYSIS
A5: Name of Faculty(s) | D5: 1 | G5: 1 | J5: 1 | M5: 1 | P5: BATCH
A6: Course Code and Name | D6: 22CDCXX | G6: XXXXXXXX XXXXX XXXXXXXX | AA6: Sem 6
A7: Branch / Year / Semester | D7: CSD | H7: 1 | L7: IV | AA7: Sem 7
AA8: Sem 8
A9: S.No | B9: Roll No. of Students | C9: Name of the student | E9: Target Plan
A10: 1 | B10: 20MER074 | E10: Percentage of Marks Expected : | I10: Average Marks of Each CO | M10: Calculated Target | O10: TARGET
A11: =A10+1 -> 2 | B11: 21MEL115
A12: =A11+1 -> 3 | B12: 21MEL116 | E12: Percentage of Students Expected to attain Expected Marks: | I12: Percentage of students secured average API and above( Previous 2 semester average) | M12: =Target!B86 -> 0 | O12: =ROUND(M12+5,0) -> 5
A13: =A12+1 -> 4 | B13: 21MEL117
A14: =A13+1 -> 5 | B14: 21MEL118
A15: =A14+1 -> 6 | B15: 21MEL119
A16: =A15+1 -> 7 | B16: 21MEL120 | E16: Total No of Students enrolled in the course: | I16: =+COUNTA(B10:B470) -> 70 | J16: Number of Students Expected to attain Expected Marks: | N16: =ROUND((O12/100)*I16,0) -> 4
A17: =A16+1 -> 8 | B17: 21MEL121
A18: =A17+1 -> 9 | B18: 21MEL122
A19: =A18+1 -> 10 | B19: 21MEL123
A20: =A19+1 -> 11 | B20: 21MEL124 | E20: Course Articulation Matrix
A21: =A20+1 -> 12 | B21: 21MEL125 | E21: COs/POs | F21: PO1 | G21: PO2 | H21: PO3 | I21: PO4 | J21: PO5 | K21: PO6 | L21: PO7 | M21: PO8 | N21: PO9 | O21: PO10 | P21: PO11 | Q21: PO12 | R21: PSO1 | S21: PSO2 | V21: PO1 | W21: PO2 | X21: PO3 | Y21: PO4 | Z21: PO5 | AA21: PO6 | AB21: PO7 | AC21: PO8 | AD21: PO9 | AE21: PO10 | AF21: PO11 | AG21: PO12 | AH21: PSO1 | AI21: PSO2
A22: =A21+1 -> 13 | B22: 21MEL126 | V22: =IF(ISBLANK(F23),"","P") | W22: =IF(ISBLANK(G23),"","P") | X22: =IF(ISBLANK(H23),"","P") | Y22: =IF(ISBLANK(I23),"","P") | Z22: =IF(ISBLANK(J23),"","P") | AA22: =IF(ISBLANK(K23),"","P") | AB22: =IF(ISBLANK(L23),"","P") | AC22: =IF(ISBLANK(M23),"","P") | ... AI22: =IF(ISBLANK(S23),"","P")
A23: =A22+1 -> 14 | B23: 21MEL127 | E23: =M31 -> CO-1 | V23: =IF(ISBLANK(F24),"","P") | W23: =IF(ISBLANK(G24),"","P") | X23: =IF(ISBLANK(H24),"","P") | Y23: =IF(ISBLANK(I24),"","P") | Z23: =IF(ISBLANK(J24),"","P") | AA23: =IF(ISBLANK(K24),"","P") | AB23: =IF(ISBLANK(L24),"","P") | AC23: =IF(ISBLANK(M24),"","P") | ... AI23: =IF(ISBLANK(S24),"","P")
A24: =A23+1 -> 15 | B24: 21MEL128 | E24: =N31 -> CO-2 | V24: =IF(ISBLANK(F25),"","P") | W24: =IF(ISBLANK(G25),"","P") | X24: =IF(ISBLANK(H25),"","P") | Y24: =IF(ISBLANK(I25),"","P") | Z24: =IF(ISBLANK(J25),"","P") | AA24: =IF(ISBLANK(K25),"","P") | AB24: =IF(ISBLANK(L25),"","P") | AC24: =IF(ISBLANK(M25),"","P") | ... AI24: =IF(ISBLANK(S25),"","P")
A25: =A24+1 -> 16 | B25: 21MEL129 | E25: =O31 -> CO-3 | V25: =IF(ISBLANK(F26),"","P") | W25: =IF(ISBLANK(G26),"","P") | X25: =IF(ISBLANK(H26),"","P") | Y25: =IF(ISBLANK(I26),"","P") | Z25: =IF(ISBLANK(J26),"","P") | AA25: =IF(ISBLANK(K26),"","P") | AB25: =IF(ISBLANK(L26),"","P") | AC25: =IF(ISBLANK(M26),"","P") | ... AI25: =IF(ISBLANK(S26),"","P")
A26: =A25+1 -> 17 | B26: 21MEL130 | E26: =P31 -> CO-4 | V26: =IF(ISBLANK(F27),"","P") | W26: =IF(ISBLANK(G27),"","P") | X26: =IF(ISBLANK(H27),"","P") | Y26: =IF(ISBLANK(I27),"","P") | Z26: =IF(ISBLANK(J27),"","P") | AA26: =IF(ISBLANK(K27),"","P") | AB26: =IF(ISBLANK(L27),"","P") | AC26: =IF(ISBLANK(M27),"","P") | ... AI26: =IF(ISBLANK(S27),"","P")
A27: =A26+1 -> 18 | B27: 21MEL131 | E27: =Q31 -> CO-5 | V27: =IF(SUM(V22:V26)=0,"-",ROUND(((SUM(V22:V26))/COUNT(V22:V26)),2)) -> - | W27: =IF(SUM(W22:W26)=0,"-",ROUND(((SUM(W22:W26))/COUNT(W22:W26)),2)) -> - | X27: =IF(SUM(X22:X26)=0,"-",ROUND(((SUM(X22:X26))/COUNT(X22:X26)),2)) -> - | Y27: =IF(SUM(Y22:Y26)=0,"-",ROUND(((SUM(Y22:Y26))/COUNT(Y22:Y26)),2)) -> - | Z27: =IF(SUM(Z22:Z26)=0,"-",ROUND(((SUM(Z22:Z26))/COUNT(Z22:Z26)),2)) -> - | AA27: =IF(SUM(AA22:AA26)=0,"-",ROUND(((SUM(AA22:AA26))/COUNT(AA22:AA26)),2)) -> - | AB27: =IF(SUM(AB22:AB26)=0,"-",ROUND(((SUM(AB22:AB26))/COUNT(AB22:AB26)),2)) -> - | AC27: =IF(SUM(AC22:AC26)=0,"-",ROUND(((SUM(AC22:AC26))/COUNT(AC22:AC26)),2)) -> - | ... AI27: =IF(SUM(AI22:AI26)=0,"-",ROUND(((SUM(AI22:AI26))/COUNT(AI22:AI26)),2)) -> -
A28: =A27+1 -> 19 | B28: 21MER051 | E28: Avg | F28: =IF(SUM(F23:F27)=0,"-",ROUND(((SUM(F23:F27))/COUNT(F23:F27)),2)) -> - | G28: =IF(SUM(G23:G27)=0,"-",ROUND(((SUM(G23:G27))/COUNT(G23:G27)),2)) -> - | H28: =IF(SUM(H23:H27)=0,"-",ROUND(((SUM(H23:H27))/COUNT(H23:H27)),2)) -> - | I28: =IF(SUM(I23:I27)=0,"-",ROUND(((SUM(I23:I27))/COUNT(I23:I27)),2)) -> - | J28: =IF(SUM(J23:J27)=0,"-",ROUND(((SUM(J23:J27))/COUNT(J23:J27)),2)) -> - | K28: =IF(SUM(K23:K27)=0,"-",ROUND(((SUM(K23:K27))/COUNT(K23:K27)),2)) -> - | L28: =IF(SUM(L23:L27)=0,"-",ROUND(((SUM(L23:L27))/COUNT(L23:L27)),2)) -> - | M28: =IF(SUM(M23:M27)=0,"-",ROUND(((SUM(M23:M27))/COUNT(M23:M27)),2)) -> - | ... S28: =IF(SUM(S23:S27)=0,"-",ROUND(((SUM(S23:S27))/COUNT(S23:S27)),2)) -> -
A29: =A28+1 -> 20 | B29: 21MER052
A30: =A29+1 -> 21 | B30: 21MER053 | G30: CO ATTAINMENT:
A31: =A30+1 -> 22 | B31: 21MER054 | G31: Course Outcomes | M31: CO-1 | N31: CO-2 | O31: CO-3 | P31: CO-4 | Q31: CO-5
A32: =A31+1 -> 23 | B32: 21MER055 | G32: Continuous Assessment Based Analysis (%) | M32: ='Course Outcome'!C464 -> 0 | N32: ='Course Outcome'!D464 -> 0 | O32: ='Course Outcome'!E464 -> 0 | P32: ='Course Outcome'!F464 -> 0 | Q32: ='Course Outcome'!G464 -> 0
A33: =A32+1 -> 24 | B33: 21MER056
A34: =A33+1 -> 25 | B34: 21MER057 | G34: Overall Attainment (100% Internal) | M34: =IFERROR(M32*1,"") -> 0 | N34: =IFERROR(N32*1,"") -> 0 | O34: =IFERROR(O32*1,"") -> 0 | P34: =IFERROR(P32*1,"") -> 0 | Q34: =IFERROR(Q32*1,"") -> 0
A35: =A34+1 -> 26 | B35: 21MER059
A36: =A35+1 -> 27 | B36: 21MER060 | E36: PO ATTAINMENT
A37: =A36+1 -> 28 | B37: 21MER061 | E37: COs/POs | F37: PO1 | G37: PO2 | H37: PO3 | I37: PO4 | J37: PO5 | K37: PO6 | L37: PO7 | M37: PO8 | N37: PO9 | O37: PO10 | P37: PO11 | Q37: PO12 | R37: PSO1 | S37: PSO2
A38: =A37+1 -> 29 | B38: 21MER062 | E38: =+E23 -> CO-1 | F38: =IF(V22="P",(F23*($M$34/100)),"-") -> - | G38: =IF(W22="P",(G23*($M$34/100)),"-") -> - | H38: =IF(X22="P",(H23*($M$34/100)),"-") -> - | I38: =IF(Y22="P",(I23*($M$34/100)),"-") -> - | J38: =IF(Z22="P",(J23*($M$34/100)),"-") -> - | K38: =IF(AA22="P",(K23*($M$34/100)),"-") -> - | L38: =IF(AB22="P",(L23*($M$34/100)),"-") -> - | M38: =IF(AC22="P",(M23*($M$34/100)),"-") -> - | ... S38: =IF(AI22="P",(S23*($M$34/100)),"-") -> -
A39: =A38+1 -> 30 | B39: 21MER063 | E39: =+E24 -> CO-2 | F39: =IF(V23="P",(F24*($N$34/100)),"-") -> - | G39: =IF(W23="P",(G24*($N$34/100)),"-") -> - | H39: =IF(X23="P",(H24*($N$34/100)),"-") -> - | I39: =IF(Y23="P",(I24*($N$34/100)),"-") -> - | J39: =IF(Z23="P",(J24*($N$34/100)),"-") -> - | K39: =IF(AA23="P",(K24*($N$34/100)),"-") -> - | L39: =IF(AB23="P",(L24*($N$34/100)),"-") -> - | M39: =IF(AC23="P",(M24*($N$34/100)),"-") -> - | ... S39: =IF(AI23="P",(S24*($N$34/100)),"-") -> -
A40: =A39+1 -> 31 | B40: 21MER064 | E40: =+E25 -> CO-3 | F40: =IF(V24="P",(F25*($O$34/100)),"-") -> - | G40: =IF(W24="P",(G25*($O$34/100)),"-") -> - | H40: =IF(X24="P",(H25*($O$34/100)),"-") -> - | I40: =IF(Y24="P",(I25*($O$34/100)),"-") -> - | J40: =IF(Z24="P",(J25*($O$34/100)),"-") -> - | K40: =IF(AA24="P",(K25*($O$34/100)),"-") -> - | L40: =IF(AB24="P",(L25*($O$34/100)),"-") -> - | M40: =IF(AC24="P",(M25*($O$34/100)),"-") -> - | ... S40: =IF(AI24="P",(S25*($O$34/100)),"-") -> -
A41: =A40+1 -> 32 | B41: 21MER065 | E41: =+E26 -> CO-4 | F41: =IF(V25="P",(F26*($P$34/100)),"-") -> - | G41: =IF(W25="P",(G26*($P$34/100)),"-") -> - | H41: =IF(X25="P",(H26*($P$34/100)),"-") -> - | I41: =IF(Y25="P",(I26*($P$34/100)),"-") -> - | J41: =IF(Z25="P",(J26*($P$34/100)),"-") -> - | K41: =IF(AA25="P",(K26*($P$34/100)),"-") -> - | L41: =IF(AB25="P",(L26*($P$34/100)),"-") -> - | M41: =IF(AC25="P",(M26*($P$34/100)),"-") -> - | ... S41: =IF(AI25="P",(S26*($P$34/100)),"-") -> -
...

Sheet Review I & II
A1: =BASE!A1 -> KONGU ENGINEERING COLLEGE, ERODE - 638 060 | S1: =BASE!A1 -> KONGU ENGINEERING COLLEGE, ERODE - 638 060
A2: =BASE!A2 -> DEPARTMENT OF ______________________________ | S2: =BASE!A2 -> DEPARTMENT OF ______________________________
A3: =BASE!A3 -> PROJECT WORK COURSE OUTCOME ANALYSIS | S3: =BASE!A3 -> PROJECT WORK COURSE OUTCOME ANALYSIS
A4: =[1]BASE!A5 -> Name of Faculty(s) | B4: : | C4: =[1]BASE!D5 -> a | G4: =[1]BASE!G5 -> b | K4: =[1]BASE!J5 -> c | O4: =[1]BASE!M5 -> d | S4: Course Code | U4: =BASE!D6 -> 22CDCXX
B5: : | C5: =BASE!D6 -> 22CDCXX | G5: =BASE!G6 -> XXXXXXXX XXXXX XXXXXXXX | S5: Course Name | U5: =BASE!G6 -> XXXXXXXX XXXXX XXXXXXXX
A6: =[1]BASE!A7 -> Branch / Year / Semester | B6: : | C6: =BASE!D7 -> CSD | G6: =BASE!H7 -> 1 | J6: =BASE!L7 -> IV | L6: No. of Tutorials | S6: =[1]BASE!A7 -> Branch / Year / Semester | U6: =BASE!D7 -> CSD | W6: =BASE!H7 -> 1 | X6: =BASE!L7 -> IV
A7: Asssesment | B7: : | C7: Review I | J7: Review II | S7: =A7 -> Asssesment | U7: Consolidated Review Marks
A9: Roll No | B9: Q. Nos | C9: 1 | D9: 2 | E9: 3 | F9: 4 | G9: 5 | H9: Total | J9: 1 | K9: 2 | L9: 3 | M9: 4 | N9: 5 | O9: Total | R9: TOT MARKS | S9: S.NO | T9: CO1 | U9: CO2 | V9: CO3 | W9: CO4 | X9: CO5
B10: Max Marks | C10: =($H$10/5) -> 4 | D10: =($H$10/5) -> 4 | E10: =($H$10/5) -> 4 | F10: =($H$10/5) -> 4 | G10: =($H$10/5) -> 4 | H10: 20 | J10: 6 | K10: 6 | L10: 6 | M10: 6 | N10: 6 | O10: 30 | T10: =SUMIF($C$11:$Q$11,1,C10:Q10) -> 10 | U10: =SUMIF($C$11:$Q$11,2,C10:Q10) -> 10 | V10: =SUMIF($C$11:$Q$11,3,C10:Q10) -> 10 | W10: =SUMIF($C$11:$Q$11,4,C10:Q10) -> 10 | X10: =SUMIF($C$11:$Q$11,5,C10:Q10) -> 10
B11: COs | C11: 1 | D11: 2 | E11: 3 | F11: 4 | G11: 5 | J11: 1 | K11: 2 | L11: 3 | M11: 4 | N11: 5
A12: =IF(BASE!B10="","",BASE!B10) -> 20MER074 | B12: : | C12: =(H12/5) -> 0 | D12: =(H12/5) -> 0 | E12: =(H12/5) -> 0 | F12: =(H12/5) -> 0 | G12: =(H12/5) -> 0 | J12: =(O12/5) -> 0 | K12: =(O12/5) -> 0 | L12: =(O12/5) -> 0 | M12: =(O12/5) -> 0 | N12: =(O12/5) -> 0 | R12: =SUM(H12,O12) -> 0 | S12: =[1]BASE!A10 -> 1 | T12: =SUMIF($C$11:$Q$11,1,C12:Q12) -> 0 | U12: =SUMIF($C$11:$Q$11,2,C12:Q12) -> 0 | V12: =SUMIF($C$11:$Q$11,3,C12:Q12) -> 0 | W12: =SUMIF($C$11:$Q$11,4,C12:Q12) -> 0 | X12: =SUMIF($C$11:$Q$11,5,C12:Q12) -> 0
A13: =IF(BASE!B11="","",BASE!B11) -> 21MEL115 | B13: : | C13: =(H13/5) -> 0 | D13: =(H13/5) -> 0 | E13: =(H13/5) -> 0 | F13: =(H13/5) -> 0 | G13: =(H13/5) -> 0 | J13: =(O13/5) -> 0 | K13: =(O13/5) -> 0 | L13: =(O13/5) -> 0 | M13: =(O13/5) -> 0 | N13: =(O13/5) -> 0 | R13: =SUM(H13,O13) -> 0 | S13: =[1]BASE!A11 -> 2 | T13: =SUMIF($C$11:$Q$11,1,C13:Q13) -> 0 | U13: =SUMIF($C$11:$Q$11,2,C13:Q13) -> 0 | V13: =SUMIF($C$11:$Q$11,3,C13:Q13) -> 0 | W13: =SUMIF($C$11:$Q$11,4,C13:Q13) -> 0 | X13: =SUMIF($C$11:$Q$11,5,C13:Q13) -> 0
A14: =IF(BASE!B12="","",BASE!B12) -> 21MEL116 | B14: : | C14: =(H14/5) -> 0 | D14: =(H14/5) -> 0 | E14: =(H14/5) -> 0 | F14: =(H14/5) -> 0 | G14: =(H14/5) -> 0 | J14: =(O14/5) -> 0 | K14: =(O14/5) -> 0 | L14: =(O14/5) -> 0 | M14: =(O14/5) -> 0 | N14: =(O14/5) -> 0 | R14: =SUM(H14,O14) -> 0 | S14: =[1]BASE!A12 -> 3 | T14: =SUMIF($C$11:$Q$11,1,C14:Q14) -> 0 | U14: =SUMIF($C$11:$Q$11,2,C14:Q14) -> 0 | V14: =SUMIF($C$11:$Q$11,3,C14:Q14) -> 0 | W14: =SUMIF($C$11:$Q$11,4,C14:Q14) -> 0 | X14: =SUMIF($C$11:$Q$11,5,C14:Q14) -> 0
A15: =IF(BASE!B13="","",BASE!B13) -> 21MEL117 | B15: : | C15: =(H15/5) -> 0 | D15: =(H15/5) -> 0 | E15: =(H15/5) -> 0 | F15: =(H15/5) -> 0 | G15: =(H15/5) -> 0 | J15: =(O15/5) -> 0 | K15: =(O15/5) -> 0 | L15: =(O15/5) -> 0 | M15: =(O15/5) -> 0 | N15: =(O15/5) -> 0 | R15: =SUM(H15,O15) -> 0 | S15: =[1]BASE!A13 -> 4 | T15: =SUMIF($C$11:$Q$11,1,C15:Q15) -> 0 | U15: =SUMIF($C$11:$Q$11,2,C15:Q15) -> 0 | V15: =SUMIF($C$11:$Q$11,3,C15:Q15) -> 0 | W15: =SUMIF($C$11:$Q$11,4,C15:Q15) -> 0 | X15: =SUMIF($C$11:$Q$11,5,C15:Q15) -> 0
A16: =IF(BASE!B14="","",BASE!B14) -> 21MEL118 | B16: : | C16: =(H16/5) -> 0 | D16: =(H16/5) -> 0 | E16: =(H16/5) -> 0 | F16: =(H16/5) -> 0 | G16: =(H16/5) -> 0 | J16: =(O16/5) -> 0 | K16: =(O16/5) -> 0 | L16: =(O16/5) -> 0 | M16: =(O16/5) -> 0 | N16: =(O16/5) -> 0 | R16: =SUM(H16,O16) -> 0 | S16: =[1]BASE!A14 -> 5 | T16: =SUMIF($C$11:$Q$11,1,C16:Q16) -> 0 | U16: =SUMIF($C$11:$Q$11,2,C16:Q16) -> 0 | V16: =SUMIF($C$11:$Q$11,3,C16:Q16) -> 0 | W16: =SUMIF($C$11:$Q$11,4,C16:Q16) -> 0 | X16: =SUMIF($C$11:$Q$11,5,C16:Q16) -> 0
A17: =IF(BASE!B15="","",BASE!B15) -> 21MEL119 | B17: : | C17: =(H17/5) -> 0 | D17: =(H17/5) -> 0 | E17: =(H17/5) -> 0 | F17: =(H17/5) -> 0 | G17: =(H17/5) -> 0 | J17: =(O17/5) -> 0 | K17: =(O17/5) -> 0 | L17: =(O17/5) -> 0 | M17: =(O17/5) -> 0 | N17: =(O17/5) -> 0 | R17: =SUM(H17,O17) -> 0 | S17: =[1]BASE!A15 -> 6 | T17: =SUMIF($C$11:$Q$11,1,C17:Q17) -> 0 | U17: =SUMIF($C$11:$Q$11,2,C17:Q17) -> 0 | V17: =SUMIF($C$11:$Q$11,3,C17:Q17) -> 0 | W17: =SUMIF($C$11:$Q$11,4,C17:Q17) -> 0 | X17: =SUMIF($C$11:$Q$11,5,C17:Q17) -> 0
A18: =IF(BASE!B16="","",BASE!B16) -> 21MEL120 | B18: : | C18: =(H18/5) -> 0 | D18: =(H18/5) -> 0 | E18: =(H18/5) -> 0 | F18: =(H18/5) -> 0 | G18: =(H18/5) -> 0 | J18: =(O18/5) -> 0 | K18: =(O18/5) -> 0 | L18: =(O18/5) -> 0 | M18: =(O18/5) -> 0 | N18: =(O18/5) -> 0 | R18: =SUM(H18,O18) -> 0 | S18: =[1]BASE!A16 -> 7 | T18: =SUMIF($C$11:$Q$11,1,C18:Q18) -> 0 | U18: =SUMIF($C$11:$Q$11,2,C18:Q18) -> 0 | V18: =SUMIF($C$11:$Q$11,3,C18:Q18) -> 0 | W18: =SUMIF($C$11:$Q$11,4,C18:Q18) -> 0 | X18: =SUMIF($C$11:$Q$11,5,C18:Q18) -> 0
A19: =IF(BASE!B17="","",BASE!B17) -> 21MEL121 | B19: : | C19: =(H19/5) -> 0 | D19: =(H19/5) -> 0 | E19: =(H19/5) -> 0 | F19: =(H19/5) -> 0 | G19: =(H19/5) -> 0 | J19: =(O19/5) -> 0 | K19: =(O19/5) -> 0 | L19: =(O19/5) -> 0 | M19: =(O19/5) -> 0 | N19: =(O19/5) -> 0 | R19: =SUM(H19,O19) -> 0 | S19: =[1]BASE!A17 -> 8 | T19: =SUMIF($C$11:$Q$11,1,C19:Q19) -> 0 | U19: =SUMIF($C$11:$Q$11,2,C19:Q19) -> 0 | V19: =SUMIF($C$11:$Q$11,3,C19:Q19) -> 0 | W19: =SUMIF($C$11:$Q$11,4,C19:Q19) -> 0 | X19: =SUMIF($C$11:$Q$11,5,C19:Q19) -> 0
A20: =IF(BASE!B18="","",BASE!B18) -> 21MEL122 | B20: : | C20: =(H20/5) -> 0 | D20: =(H20/5) -> 0 | E20: =(H20/5) -> 0 | F20: =(H20/5) -> 0 | G20: =(H20/5) -> 0 | J20: =(O20/5) -> 0 | K20: =(O20/5) -> 0 | L20: =(O20/5) -> 0 | M20: =(O20/5) -> 0 | N20: =(O20/5) -> 0 | R20: =SUM(H20,O20) -> 0 | S20: =[1]BASE!A18 -> 9 | T20: =SUMIF($C$11:$Q$11,1,C20:Q20) -> 0 | U20: =SUMIF($C$11:$Q$11,2,C20:Q20) -> 0 | V20: =SUMIF($C$11:$Q$11,3,C20:Q20) -> 0 | W20: =SUMIF($C$11:$Q$11,4,C20:Q20) -> 0 | X20: =SUMIF($C$11:$Q$11,5,C20:Q20) -> 0
A21: =IF(BASE!B19="","",BASE!B19) -> 21MEL123 | B21: : | C21: =(H21/5) -> 0 | D21: =(H21/5) -> 0 | E21: =(H21/5) -> 0 | F21: =(H21/5) -> 0 | G21: =(H21/5) -> 0 | J21: =(O21/5) -> 0 | K21: =(O21/5) -> 0 | L21: =(O21/5) -> 0 | M21: =(O21/5) -> 0 | N21: =(O21/5) -> 0 | R21: =SUM(H21,O21) -> 0 | S21: =[1]BASE!A19 -> 10 | T21: =SUMIF($C$11:$Q$11,1,C21:Q21) -> 0 | U21: =SUMIF($C$11:$Q$11,2,C21:Q21) -> 0 | V21: =SUMIF($C$11:$Q$11,3,C21:Q21) -> 0 | W21: =SUMIF($C$11:$Q$11,4,C21:Q21) -> 0 | X21: =SUMIF($C$11:$Q$11,5,C21:Q21) -> 0
A22: =IF(BASE!B20="","",BASE!B20) -> 21MEL124 | B22: : | C22: =(H22/5) -> 0 | D22: =(H22/5) -> 0 | E22: =(H22/5) -> 0 | F22: =(H22/5) -> 0 | G22: =(H22/5) -> 0 | J22: =(O22/5) -> 0 | K22: =(O22/5) -> 0 | L22: =(O22/5) -> 0 | M22: =(O22/5) -> 0 | N22: =(O22/5) -> 0 | R22: =SUM(H22,O22) -> 0 | S22: =[1]BASE!A20 -> 11 | T22: =SUMIF($C$11:$Q$11,1,C22:Q22) -> 0 | U22: =SUMIF($C$11:$Q$11,2,C22:Q22) -> 0 | V22: =SUMIF($C$11:$Q$11,3,C22:Q22) -> 0 | W22: =SUMIF($C$11:$Q$11,4,C22:Q22) -> 0 | X22: =SUMIF($C$11:$Q$11,5,C22:Q22) -> 0
A23: =IF(BASE!B21="","",BASE!B21) -> 21MEL125 | B23: : | C23: =(H23/5) -> 0 | D23: =(H23/5) -> 0 | E23: =(H23/5) -> 0 | F23: =(H23/5) -> 0 | G23: =(H23/5) -> 0 | J23: =(O23/5) -> 0 | K23: =(O23/5) -> 0 | L23: =(O23/5) -> 0 | M23: =(O23/5) -> 0 | N23: =(O23/5) -> 0 | R23: =SUM(H23,O23) -> 0 | S23: =[1]BASE!A21 -> 12 | T23: =SUMIF($C$11:$Q$11,1,C23:Q23) -> 0 | U23: =SUMIF($C$11:$Q$11,2,C23:Q23) -> 0 | V23: =SUMIF($C$11:$Q$11,3,C23:Q23) -> 0 | W23: =SUMIF($C$11:$Q$11,4,C23:Q23) -> 0 | X23: =SUMIF($C$11:$Q$11,5,C23:Q23) -> 0
... A461: =IF(BASE!B459="","",BASE!B459) | B461: : | C461: =(H461/5) -> 0 | D461: =(H461/5) -> 0 | E461: =(H461/5) -> 0 | F461: =(H461/5) -> 0 | G461: =(H461/5) -> 0 | J461: =(O461/5) -> 0 | K461: =(O461/5) -> 0 | L461: =(O461/5) -> 0 | M461: =(O461/5) -> 0 | N461: =(O461/5) -> 0 | R461: =SUM(H461,O461) -> 0 | S461: =[1]BASE!A459 -> 450 | T461: =SUMIF($C$11:$Q$11,1,C461:Q461) -> 0 | U461: =SUMIF($C$11:$Q$11,2,C461:Q461) -> 0 | V461: =SUMIF($C$11:$Q$11,3,C461:Q461) -> 0 | W461: =SUMIF($C$11:$Q$11,4,C461:Q461) -> 0 | X461: =SUMIF($C$11:$Q$11,5,C461:Q461) -> 0

Sheet ESE
A1: =BASE!A1 -> KONGU ENGINEERING COLLEGE, ERODE - 638 060 | Y1: =BASE!A1 -> KONGU ENGINEERING COLLEGE, ERODE - 638 060
A2: =BASE!A2 -> DEPARTMENT OF ______________________________ | Y2: =BASE!A2 -> DEPARTMENT OF ______________________________
A3: =BASE!A3 -> PROJECT WORK COURSE OUTCOME ANALYSIS | Y3: =BASE!A3 -> PROJECT WORK COURSE OUTCOME ANALYSIS
A4: =[2]BASE!A5 -> Name of Faculty(s) | B4: : | C4: =BASE!D5 -> 1 | H4: =BASE!G5 -> 1 | N4: =BASE!J5 -> 1 | S4: =BASE!M5 -> 1 | Y4: Course Code | AA4: =C5 -> 22CDCXX
A5: =[2]BASE!A6 -> Course Code and Name | B5: : | C5: =BASE!D6 -> 22CDCXX | G5: =BASE!G6 -> XXXXXXXX XXXXX XXXXXXXX | Y5: Course Name | AA5: =G5 -> XXXXXXXX XXXXX XXXXXXXX
A6: =[2]BASE!A7 -> Branch / Year / Semester | B6: : | C6: =BASE!D7 -> CSD | G6: =BASE!H7 -> 1 | I6: =BASE!L7 -> IV | K6: Date | N6: : | Y6: =[2]BASE!A7 -> Branch / Year / Semester | AA6: =BASE!D7 -> CSD | AC6: =BASE!H7 -> 1 | AD6: =BASE!L7 -> IV
A7: End semester Examination | B7: : | C7: ESE | G7: Total No. of Students | K7: : | L7: =ROWS(A12:A480)-COUNTIF(A12:A480,"") -> 70 | O7: Max marks | R7: : | Y7: End Semester Examination | AA7: =C7 -> ESE
A9: Roll No | B9: Q. Nos | H9: Total | X9: TOT MARKS | Y9: S.NO | Z9: CO1 | AA9: CO2 | AB9: CO3 | AC9: CO4 | AD9: CO5
B10: Max Marks | C10: 10 | D10: 10 | E10: 10 | F10: 10 | G10: 10 | H10: 50 | Z10: =SUMIF($C$11:$V$11,1,C10:V10) -> 10 | AA10: =SUMIF($C$11:$V$11,2,C10:V10) -> 10 | AB10: =SUMIF($C$11:$V$11,3,C10:V10) -> 10 | AC10: =SUMIF($C$11:$V$11,4,C10:V10) -> 10 | AD10: =SUMIF($C$11:$V$11,5,C10:V10) -> 10
B11: COs | C11: 1 | D11: 2 | E11: 3 | F11: 4 | G11: 5
A12: =IF(BASE!B10="","",BASE!B10) -> 20MER074 | B12: : | C12: =(H12/5) -> 0 | D12: =(H12/5) -> 0 | E12: =(H12/5) -> 0 | F12: =(H12/5) -> 0 | G12: =(H12/5) -> 0 | X12: =SUM(C12:V12) -> 0 | Y12: =[2]BASE!A10 -> 1 | Z12: =SUMIF($C$11:$V$11,1,C12:V12) -> 0 | AA12: =SUMIF($C$11:$V$11,2,C12:V12) -> 0 | AB12: =SUMIF($C$11:$V$11,3,C12:V12) -> 0 | AC12: =SUMIF($C$11:$V$11,4,C12:V12) -> 0 | AD12: =SUMIF($C$11:$V$11,5,C12:V12) -> 0
A13: =IF(BASE!B11="","",BASE!B11) -> 21MEL115 | B13: : | C13: =(H13/5) -> 0 | D13: =(H13/5) -> 0 | E13: =(H13/5) -> 0 | F13: =(H13/5) -> 0 | G13: =(H13/5) -> 0 | X13: =SUM(C13:V13) -> 0 | Y13: =[2]BASE!A11 -> 2 | Z13: =SUMIF($C$11:$V$11,1,C13:V13) -> 0 | AA13: =SUMIF($C$11:$V$11,2,C13:V13) -> 0 | AB13: =SUMIF($C$11:$V$11,3,C13:V13) -> 0 | AC13: =SUMIF($C$11:$V$11,4,C13:V13) -> 0 | AD13: =SUMIF($C$11:$V$11,5,C13:V13) -> 0
A14: =IF(BASE!B12="","",BASE!B12) -> 21MEL116 | B14: : | C14: =(H14/5) -> 0 | D14: =(H14/5) -> 0 | E14: =(H14/5) -> 0 | F14: =(H14/5) -> 0 | G14: =(H14/5) -> 0 | X14: =SUM(C14:V14) -> 0 | Y14: =[2]BASE!A12 -> 3 | Z14: =SUMIF($C$11:$V$11,1,C14:V14) -> 0 | AA14: =SUMIF($C$11:$V$11,2,C14:V14) -> 0 | AB14: =SUMIF($C$11:$V$11,3,C14:V14) -> 0 | AC14: =SUMIF($C$11:$V$11,4,C14:V14) -> 0 | AD14: =SUMIF($C$11:$V$11,5,C14:V14) -> 0
A15: =IF(BASE!B13="","",BASE!B13) -> 21MEL117 | B15: : | C15: =(H15/5) -> 0 | D15: =(H15/5) -> 0 | E15: =(H15/5) -> 0 | F15: =(H15/5) -> 0 | G15: =(H15/5) -> 0 | X15: =SUM(C15:V15) -> 0 | Y15: =[2]BASE!A13 -> 4 | Z15: =SUMIF($C$11:$V$11,1,C15:V15) -> 0 | AA15: =SUMIF($C$11:$V$11,2,C15:V15) -> 0 | AB15: =SUMIF($C$11:$V$11,3,C15:V15) -> 0 | AC15: =SUMIF($C$11:$V$11,4,C15:V15) -> 0 | AD15: =SUMIF($C$11:$V$11,5,C15:V15) -> 0
A16: =IF(BASE!B14="","",BASE!B14) -> 21MEL118 | B16: : | C16: =(H16/5) -> 0 | D16: =(H16/5) -> 0 | E16: =(H16/5) -> 0 | F16: =(H16/5) -> 0 | G16: =(H16/5) -> 0 | X16: =SUM(C16:V16) -> 0 | Y16: =[2]BASE!A14 -> 5 | Z16: =SUMIF($C$11:$V$11,1,C16:V16) -> 0 | AA16: =SUMIF($C$11:$V$11,2,C16:V16) -> 0 | AB16: =SUMIF($C$11:$V$11,3,C16:V16) -> 0 | AC16: =SUMIF($C$11:$V$11,4,C16:V16) -> 0 | AD16: =SUMIF($C$11:$V$11,5,C16:V16) -> 0
A17: =IF(BASE!B15="","",BASE!B15) -> 21MEL119 | B17: : | C17: =(H17/5) -> 0 | D17: =(H17/5) -> 0 | E17: =(H17/5) -> 0 | F17: =(H17/5) -> 0 | G17: =(H17/5) -> 0 | X17: =SUM(C17:V17) -> 0 | Y17: =[2]BASE!A15 -> 6 | Z17: =SUMIF($C$11:$V$11,1,C17:V17) -> 0 | AA17: =SUMIF($C$11:$V$11,2,C17:V17) -> 0 | AB17: =SUMIF($C$11:$V$11,3,C17:V17) -> 0 | AC17: =SUMIF($C$11:$V$11,4,C17:V17) -> 0 | AD17: =SUMIF($C$11:$V$11,5,C17:V17) -> 0
A18: =IF(BASE!B16="","",BASE!B16) -> 21MEL120 | B18: : | C18: =(H18/5) -> 0 | D18: =(H18/5) -> 0 | E18: =(H18/5) -> 0 | F18: =(H18/5) -> 0 | G18: =(H18/5) -> 0 | X18: =SUM(C18:V18) -> 0 | Y18: =[2]BASE!A16 -> 7 | Z18: =SUMIF($C$11:$V$11,1,C18:V18) -> 0 | AA18: =SUMIF($C$11:$V$11,2,C18:V18) -> 0 | AB18: =SUMIF($C$11:$V$11,3,C18:V18) -> 0 | AC18: =SUMIF($C$11:$V$11,4,C18:V18) -> 0 | AD18: =SUMIF($C$11:$V$11,5,C18:V18) -> 0
A19: =IF(BASE!B17="","",BASE!B17) -> 21MEL121 | B19: : | C19: =(H19/5) -> 0 | D19: =(H19/5) -> 0 | E19: =(H19/5) -> 0 | F19: =(H19/5) -> 0 | G19: =(H19/5) -> 0 | X19: =SUM(C19:V19) -> 0 | Y19: =[2]BASE!A17 -> 8 | Z19: =SUMIF($C$11:$V$11,1,C19:V19) -> 0 | AA19: =SUMIF($C$11:$V$11,2,C19:V19) -> 0 | AB19: =SUMIF($C$11:$V$11,3,C19:V19) -> 0 | AC19: =SUMIF($C$11:$V$11,4,C19:V19) -> 0 | AD19: =SUMIF($C$11:$V$11,5,C19:V19) -> 0
A20: =IF(BASE!B18="","",BASE!B18) -> 21MEL122 | B20: : | C20: =(H20/5) -> 0 | D20: =(H20/5) -> 0 | E20: =(H20/5) -> 0 | F20: =(H20/5) -> 0 | G20: =(H20/5) -> 0 | X20: =SUM(C20:V20) -> 0 | Y20: =[2]BASE!A18 -> 9 | Z20: =SUMIF($C$11:$V$11,1,C20:V20) -> 0 | AA20: =SUMIF($C$11:$V$11,2,C20:V20) -> 0 | AB20: =SUMIF($C$11:$V$11,3,C20:V20) -> 0 | AC20: =SUMIF($C$11:$V$11,4,C20:V20) -> 0 | AD20: =SUMIF($C$11:$V$11,5,C20:V20) -> 0
A21: =IF(BASE!B19="","",BASE!B19) -> 21MEL123 | B21: : | C21: =(H21/5) -> 0 | D21: =(H21/5) -> 0 | E21: =(H21/5) -> 0 | F21: =(H21/5) -> 0 | G21: =(H21/5) -> 0 | X21: =SUM(C21:V21) -> 0 | Y21: =[2]BASE!A19 -> 10 | Z21: =SUMIF($C$11:$V$11,1,C21:V21) -> 0 | AA21: =SUMIF($C$11:$V$11,2,C21:V21) -> 0 | AB21: =SUMIF($C$11:$V$11,3,C21:V21) -> 0 | AC21: =SUMIF($C$11:$V$11,4,C21:V21) -> 0 | AD21: =SUMIF($C$11:$V$11,5,C21:V21) -> 0
A22: =IF(BASE!B20="","",BASE!B20) -> 21MEL124 | B22: : | C22: =(H22/5) -> 0 | D22: =(H22/5) -> 0 | E22: =(H22/5) -> 0 | F22: =(H22/5) -> 0 | G22: =(H22/5) -> 0 | X22: =SUM(C22:V22) -> 0 | Y22: =[2]BASE!A20 -> 11 | Z22: =SUMIF($C$11:$V$11,1,C22:V22) -> 0 | AA22: =SUMIF($C$11:$V$11,2,C22:V22) -> 0 | AB22: =SUMIF($C$11:$V$11,3,C22:V22) -> 0 | AC22: =SUMIF($C$11:$V$11,4,C22:V22) -> 0 | AD22: =SUMIF($C$11:$V$11,5,C22:V22) -> 0
A23: =IF(BASE!B21="","",BASE!B21) -> 21MEL125 | B23: : | C23: =(H23/5) -> 0 | D23: =(H23/5) -> 0 | E23: =(H23/5) -> 0 | F23: =(H23/5) -> 0 | G23: =(H23/5) -> 0 | X23: =SUM(C23:V23) -> 0 | Y23: =[2]BASE!A21 -> 12 | Z23: =SUMIF($C$11:$V$11,1,C23:V23) -> 0 | AA23: =SUMIF($C$11:$V$11,2,C23:V23) -> 0 | AB23: =SUMIF($C$11:$V$11,3,C23:V23) -> 0 | AC23: =SUMIF($C$11:$V$11,4,C23:V23) -> 0 | AD23: =SUMIF($C$11:$V$11,5,C23:V23) -> 0
... A461: =IF(BASE!B459="","",BASE!B459) | B461: : | C461: =(H461/5) -> 0 | D461: =(H461/5) -> 0 | E461: =(H461/5) -> 0 | F461: =(H461/5) -> 0 | G461: =(H461/5) -> 0 | X461: =SUM(C461:V461) -> 0 | Y461: =[2]BASE!A459 -> 450 | Z461: =SUMIF($C$11:$V$11,1,C461:V461) -> 0 | AA461: =SUMIF($C$11:$V$11,2,C461:V461) -> 0 | AB461: =SUMIF($C$11:$V$11,3,C461:V461) -> 0 | AC461: =SUMIF($C$11:$V$11,4,C461:V461) -> 0 | AD461: =SUMIF($C$11:$V$11,5,C461:V461) -> 0

Sheet Course Outcome
A1: =BASE!A1 -> KONGU ENGINEERING COLLEGE, ERODE - 638 060
A2: =BASE!A2 -> DEPARTMENT OF ______________________________
A3: =BASE!A3 -> PROJECT WORK COURSE OUTCOME ANALYSIS
A4: =[2]BASE!A5 -> Name of Faculty(s) | B4: : | C4: =BASE!D5 -> 1 | E4: =BASE!G5 -> 1 | H4: =BASE!J5 -> 1 | K4: =BASE!M5 -> 1
A5: =[2]BASE!A6 -> Course Code and Name | B5: : | C5: =BASE!D6 -> 22CDCXX | E5: =BASE!G6 -> XXXXXXXX XXXXX XXXXXXXX
A6: =[2]BASE!A7 -> Branch / Year / Semester | B6: : | C6: =BASE!D7 -> CSD | F6: =BASE!H7 -> 1 | G6: =BASE!L7 -> IV
A7: Total No of Students | B7: =BASE!I16 -> 70 | C7: Percentage of Students Expected | G7: =BASE!N16 -> 4
C8: CO - 1 | D8: CO - 2 | E8: CO - 3 | F8: CO - 4 | G8: CO - 5
A9: Maxmum Marks/ Grade Evaluated | C9: =[2]ESE!Z10 -> 20 | D9: =[2]ESE!AA10 -> 20 | E9: =[2]ESE!AB10 -> 20 | F9: =[2]ESE!AC10 -> 20 | G9: =[2]ESE!AD10 -> 20
A10: Roll No of Students
A11: =BASE!B10 -> 20MER074 | B11: : | C11: ='Review I & II'!T12+ESE!Z12 -> 0 | D11: ='Review I & II'!U12+ESE!AA12 -> 0 | E11: ='Review I & II'!V12+ESE!AB12 -> 0 | F11: ='Review I & II'!W12+ESE!AC12 -> 0 | G11: ='Review I & II'!X12+ESE!AD12 -> 0
A12: =BASE!B11 -> 21MEL115 | B12: : | C12: ='Review I & II'!T13+ESE!Z13 -> 0 | D12: ='Review I & II'!U13+ESE!AA13 -> 0 | E12: ='Review I & II'!V13+ESE!AB13 -> 0 | F12: ='Review I & II'!W13+ESE!AC13 -> 0 | G12: ='Review I & II'!X13+ESE!AD13 -> 0
A13: =BASE!B12 -> 21MEL116 | B13: : | C13: ='Review I & II'!T14+ESE!Z14 -> 0 | D13: ='Review I & II'!U14+ESE!AA14 -> 0 | E13: ='Review I & II'!V14+ESE!AB14 -> 0 | F13: ='Review I & II'!W14+ESE!AC14 -> 0 | G13: ='Review I & II'!X14+ESE!AD14 -> 0
A14: =BASE!B13 -> 21MEL117 | B14: : | C14: ='Review I & II'!T15+ESE!Z15 -> 0 | D14: ='Review I & II'!U15+ESE!AA15 -> 0 | E14: ='Review I & II'!V15+ESE!AB15 -> 0 | F14: ='Review I & II'!W15+ESE!AC15 -> 0 | G14: ='Review I & II'!X15+ESE!AD15 -> 0
A15: =BASE!B14 -> 21MEL118 | B15: : | C15: ='Review I & II'!T16+ESE!Z16 -> 0 | D15: ='Review I & II'!U16+ESE!AA16 -> 0 | E15: ='Review I & II'!V16+ESE!AB16 -> 0 | F15: ='Review I & II'!W16+ESE!AC16 -> 0 | G15: ='Review I & II'!X16+ESE!AD16 -> 0
A16: =BASE!B15 -> 21MEL119 | B16: : | C16: ='Review I & II'!T17+ESE!Z17 -> 0 | D16: ='Review I & II'!U17+ESE!AA17 -> 0 | E16: ='Review I & II'!V17+ESE!AB17 -> 0 | F16: ='Review I & II'!W17+ESE!AC17 -> 0 | G16: ='Review I & II'!X17+ESE!AD17 -> 0
A17: =BASE!B16 -> 21MEL120 | B17: : | C17: ='Review I & II'!T18+ESE!Z18 -> 0 | D17: ='Review I & II'!U18+ESE!AA18 -> 0 | E17: ='Review I & II'!V18+ESE!AB18 -> 0 | F17: ='Review I & II'!W18+ESE!AC18 -> 0 | G17: ='Review I & II'!X18+ESE!AD18 -> 0
A18: =BASE!B17 -> 21MEL121 | B18: : | C18: ='Review I & II'!T19+ESE!Z19 -> 0 | D18: ='Review I & II'!U19+ESE!AA19 -> 0 | E18: ='Review I & II'!V19+ESE!AB19 -> 0 | F18: ='Review I & II'!W19+ESE!AC19 -> 0 | G18: ='Review I & II'!X19+ESE!AD19 -> 0
A19: =BASE!B18 -> 21MEL122 | B19: : | C19: ='Review I & II'!T20+ESE!Z20 -> 0 | D19: ='Review I & II'!U20+ESE!AA20 -> 0 | E19: ='Review I & II'!V20+ESE!AB20 -> 0 | F19: ='Review I & II'!W20+ESE!AC20 -> 0 | G19: ='Review I & II'!X20+ESE!AD20 -> 0
A20: =BASE!B19 -> 21MEL123 | B20: : | C20: ='Review I & II'!T21+ESE!Z21 -> 0 | D20: ='Review I & II'!U21+ESE!AA21 -> 0 | E20: ='Review I & II'!V21+ESE!AB21 -> 0 | F20: ='Review I & II'!W21+ESE!AC21 -> 0 | G20: ='Review I & II'!X21+ESE!AD21 -> 0
A21: =BASE!B20 -> 21MEL124 | B21: : | C21: ='Review I & II'!T22+ESE!Z22 -> 0 | D21: ='Review I & II'!U22+ESE!AA22 -> 0 | E21: ='Review I & II'!V22+ESE!AB22 -> 0 | F21: ='Review I & II'!W22+ESE!AC22 -> 0 | G21: ='Review I & II'!X22+ESE!AD22 -> 0
A22: =BASE!B21 -> 21MEL125 | B22: : | C22: ='Review I & II'!T23+ESE!Z23 -> 0 | D22: ='Review I & II'!U23+ESE!AA23 -> 0 | E22: ='Review I & II'!V23+ESE!AB23 -> 0 | F22: ='Review I & II'!W23+ESE!AC23 -> 0 | G22: ='Review I & II'!X23+ESE!AD23 -> 0
... A460: =BASE!B459 -> 0 | B460: : | C460: ='Review I & II'!T461+ESE!Z461 -> 0 | D460: ='Review I & II'!U461+ESE!AA461 -> 0 | E460: ='Review I & II'!V461+ESE!AB461 -> 0 | F460: ='Review I & II'!W461+ESE!AC461 -> 0 | G460: ='Review I & II'!X461+ESE!AD461 -> 0
A462: Expected Marks | C462: =IFERROR(AVERAGEIF(C11:C460,"<>0"),"") | D462: =IFERROR(AVERAGEIF(D11:D460,"<>0"),"") | E462: =IFERROR(AVERAGEIF(E11:E460,"<>0"),"") | F462: =IFERROR(AVERAGEIF(F11:F460,"<>0"),"") | G462: =IFERROR(AVERAGEIF(G11:G460,"<>0"),"")
A463: No of Students obtained Expected Marks | C463: =COUNTIF(C11:C460,">="&C462) -> 0 | D463: =COUNTIF(D11:D460,">="&D462) -> 0 | E463: =COUNTIF(E11:E460,">="&E462) -> 0 | F463: =COUNTIF(F11:F460,">="&F462) -> 0 | G463: =COUNTIF(G11:G460,">="&G462) -> 0
A464: Percentage of CO / ESE Attainment | C464: =IFERROR(MIN((C463/$G$7)*100,100),"") -> 0 | D464: =IFERROR(MIN((D463/$G$7)*100,100),"") -> 0 | E464: =IFERROR(MIN((E463/$G$7)*100,100),"") -> 0 | F464: =IFERROR(MIN((F463/$G$7)*100,100),"") -> 0 | G464: =IFERROR(MIN((G463/$G$7)*100,100),"") -> 0

Sheet Course Ass Report
A1: =BASE!A1 -> KONGU ENGINEERING COLLEGE, ERODE - 638 060
A2: =BASE!A2 -> DEPARTMENT OF ______________________________
A3: =BASE!A3 -> PROJECT WORK COURSE OUTCOME ANALYSIS
A5: =BASE!A5 -> Name of Faculty(s) | D5: =BASE!D5 -> 1 | G5: =BASE!G5 -> 1 | J5: =BASE!J5 -> 1 | M5: =BASE!M5 -> 1
A6: =BASE!A6 -> Course Code and Name | D6: =BASE!D6 -> 22CDCXX | G6: =BASE!G6 -> XXXXXXXX XXXXX XXXXXXXX
A7: =BASE!A7 -> Branch / Year / Semester | D7: =BASE!D7 -> CSD | H7: =BASE!H7 -> 1 | L7: =BASE!L7 -> IV
A9: Impact of delivery methods
A14: POs attainment remarks
A15: POs | B15: Target Level | C15: Attainment Level | D15: % of Attainment | E15: Observations | H15: Actions for improvement
A17: PO1 | B17: =BASE!F28 -> - | C17: =BASE!F43 -> - | D17: =IF(C17="-","-",(C17/B17)) -> -
A18: PO2 | B18: =BASE!G28 -> - | C18: =BASE!G43 -> - | D18: =IF(C18="-","-",(C18/B18)) -> -
A19: PO3 | B19: =BASE!H28 -> - | C19: =BASE!H43 -> - | D19: =IF(C19="-","-",(C19/B19)) -> -
A20: PO4 | B20: =BASE!I28 -> - | C20: =BASE!I43 -> - | D20: =IF(C20="-","-",(C20/B20)) -> -
A21: PO5 | B21: =BASE!J28 -> - | C21: =BASE!J43 -> - | D21: =IF(C21="-","-",(C21/B21)) -> -
A22: PO6 | B22: =BASE!K28 -> - | C22: =BASE!K43 -> - | D22: =IF(C22="-","-",(C22/B22)) -> -
A23: PO7 | B23: =BASE!L28 -> - | C23: =BASE!L43 -> - | D23: =IF(C23="-","-",(C23/B23)) -> -
A24: PO8 | B24: =BASE!M28 -> - | C24: =BASE!M43 -> - | D24: =IF(C24="-","-",(C24/B24)) -> -
A25: PO9 | B25: =BASE!N28 -> - | C25: =BASE!N43 -> - | D25: =IF(C25="-","-",(C25/B25)) -> -
A26: PO10 | B26: =BASE!O28 -> - | C26: =BASE!O43 -> - | D26: =IF(C26="-","-",(C26/B26)) -> -
A27: PO11 | B27: =BASE!P28 -> - | C27: =BASE!P43 -> - | D27: =IF(C27="-","-",(C27/B27)) -> -
A28: PO12 | B28: =BASE!Q28 -> - | C28: =BASE!Q43 -> - | D28: =IF(C28="-","-",(C28/B28)) -> -
A29: PSO1 | B29: =[2]BASE!R28 -> - | C29: =[2]BASE!R43 -> - | D29: =IF(C29="-","-",(C29/B29)) -> -
A30: PSO2 | B30: =[2]BASE!S28 -> - | C30: =[2]BASE!S43 -> - | D30: =IF(C30="-","-",(C30/B30)) -> -
B35: Course Handling faculty | E35: Course Coordinator | I35: Year Coordinator | M35: HoD
